<?xml version="1.0" ?>
<mujoco>
  <compiler angle="radian" autolimits="true" assetdir="assets" meshdir="assets" texturedir="assets"/>
  <visual>
    <headlight diffuse="0.6 0.6 0.6" ambient="0.3 0.3 0.3" specular="0 0 0"/>
    <rgba haze="0.15 0.25 0.35 1"/>
    <global azimuth="150" elevation="-20" offwidth="1280" offheight="1024"/>
  </visual>
  <asset>
    <material name="concrete-slab-concrete" rgba="0.2 0.2 0.2 1" shininess="0.5"/>
    <texture type="skybox" builtin="gradient" rgb1="0.9 0.7 0.9" rgb2="0.94 0.97 0.97" width="512" height="3072"/>
    <texture type="2d" name="groundplane" builtin="checker" mark="edge" rgb1="0.2 0.3 0.4" rgb2="0.1 0.2 0.3" markrgb="0.8 0.8 0.8" width="300" height="300"/>
    <material name="groundplane" texture="groundplane" texuniform="true" texrepeat="5 5" reflectance="0.2"/>
  </asset>
  <option cone="elliptic" impratio="10"/>
  <default>
    <default class="robot">
      <default class="motor">
        <joint />
        <position kp="0.1"  />
      </default>
      <default class="visual">
        <geom material="visualgeom" contype="0" conaffinity="0" group="2" />
      </default>
      <default class="collision">
        <geom material="collision_material" condim="3" contype="0" conaffinity="1" priority="1" group="2" solref="0.005 1" solimp="0.99 0.999 1e-05" friction="1 0.01 0.01" />
      </default>
      <default class="left-collision">
        <geom material="left-collision_material" condim="3" contype="0" conaffinity="1" priority="1" group="2" solref="0.005 1" solimp="0.99 0.999 1e-05" friction="1 0.01 0.01" />
      </default>
    </default>
  </default>
  <asset>
    <material name="default_material" rgba="0.7 0.7 0.7 1" />
    <material name="collision_material" rgba="0.7 0.7 0.7 0.5" />
    <material name="left-collision_material" rgba="0.7 0.7 0.7 0.5" />
    <material name="box" rgba="0.9 0.3 0.3 1" />
    <!-- panda -->
    <mesh name="link0.stl" file="./franka_description/meshes/collision/link0.stl" />
    <mesh name="link1.stl" file="./franka_description/meshes/collision/link1.stl" />
    <mesh name="link2.stl" file="./franka_description/meshes/collision/link2.stl" />
    <mesh name="link3.stl" file="./franka_description/meshes/collision/link3.stl" />
    <mesh name="link4.stl" file="./franka_description/meshes/collision/link4.stl" />
    <mesh name="link5.stl" file="./franka_description/meshes/collision/link5.stl" />
    <mesh name="link6.stl" file="./franka_description/meshes/collision/link6.stl" />
    <mesh name="link7.stl" file="./franka_description/meshes/collision/link7.stl" />
    <!-- left hand -->
    <mesh name="ll_dg_mount_c.STL" file="./meshes/dg5f_left/collision/ll_dg_mount_c.STL" />
    <mesh name="ll_dg_base_c.STL" file="./meshes/dg5f_left/collision/ll_dg_base_c.STL" />
    <mesh name="ll_dg_palm_c.STL" file="./meshes/dg5f_left/collision/ll_dg_palm_c.STL" />
    <mesh name="ll_dg_1_1_c.STL" file="./meshes/dg5f_left/collision/ll_dg_1_1_c.STL" />
    <mesh name="ll_dg_1_2_c.STL" file="./meshes/dg5f_left/collision/ll_dg_1_2_c.STL" />
    <mesh name="ll_dg_1_3_c.STL" file="./meshes/dg5f_left/collision/ll_dg_1_3_c.STL" />
    <mesh name="ll_dg_1_4_c.STL" file="./meshes/dg5f_left/collision/ll_dg_1_4_c.STL" />
    <mesh name="ll_dg_1_tip_c.STL" file="./meshes/dg5f_left/collision/ll_dg_1_tip_c.STL" />
    <mesh name="ll_dg_2_1_c.STL" file="./meshes/dg5f_left/collision/ll_dg_2_1_c.STL" />
    <mesh name="ll_dg_2_2_c.STL" file="./meshes/dg5f_left/collision/ll_dg_2_2_c.STL" />
    <mesh name="ll_dg_2_3_c.STL" file="./meshes/dg5f_left/collision/ll_dg_2_3_c.STL" />
    <mesh name="ll_dg_2_4_c.STL" file="./meshes/dg5f_left/collision/ll_dg_2_4_c.STL" />
    <mesh name="ll_dg_2_tip_c.STL" file="./meshes/dg5f_left/collision/ll_dg_2_tip_c.STL" />
    <mesh name="ll_dg_3_1_c.STL" file="./meshes/dg5f_left/collision/ll_dg_3_1_c.STL" />
    <mesh name="ll_dg_3_2_c.STL" file="./meshes/dg5f_left/collision/ll_dg_3_2_c.STL" />
    <mesh name="ll_dg_3_3_c.STL" file="./meshes/dg5f_left/collision/ll_dg_3_3_c.STL" />
    <mesh name="ll_dg_3_4_c.STL" file="./meshes/dg5f_left/collision/ll_dg_3_4_c.STL" />
    <mesh name="ll_dg_3_tip_c.STL" file="./meshes/dg5f_left/collision/ll_dg_3_tip_c.STL" />
    <mesh name="ll_dg_4_1_c.STL" file="./meshes/dg5f_left/collision/ll_dg_4_1_c.STL" />
    <mesh name="ll_dg_4_2_c.STL" file="./meshes/dg5f_left/collision/ll_dg_4_2_c.STL" />
    <mesh name="ll_dg_4_3_c.STL" file="./meshes/dg5f_left/collision/ll_dg_4_3_c.STL" />
    <mesh name="ll_dg_4_4_c.STL" file="./meshes/dg5f_left/collision/ll_dg_4_4_c.STL" />
    <mesh name="ll_dg_4_tip_c.STL" file="./meshes/dg5f_left/collision/ll_dg_4_tip_c.STL" />
    <mesh name="ll_dg_5_1_c.STL" file="./meshes/dg5f_left/collision/ll_dg_5_1_c.STL" />
    <mesh name="ll_dg_5_2_c.STL" file="./meshes/dg5f_left/collision/ll_dg_5_2_c.STL" />
    <mesh name="ll_dg_5_3_c.STL" file="./meshes/dg5f_left/collision/ll_dg_5_3_c.STL" />
    <mesh name="ll_dg_5_4_c.STL" file="./meshes/dg5f_left/collision/ll_dg_5_4_c.STL" />
    <mesh name="ll_dg_5_tip_c.STL" file="./meshes/dg5f_left/collision/ll_dg_5_tip_c.STL" />
    <!-- right hand -->
    <mesh name="rl_dg_mount_c.STL" file="./meshes/dg5f_right/collision/rl_dg_mount_c.STL" />
    <mesh name="rl_dg_base_c.STL" file="./meshes/dg5f_right/collision/rl_dg_base_c.STL" />
    <mesh name="rl_dg_palm_c.STL" file="./meshes/dg5f_right/collision/rl_dg_palm_c.STL" />
    <mesh name="rl_dg_1_1_c.STL" file="./meshes/dg5f_right/collision/rl_dg_1_1_c.STL" />
    <mesh name="rl_dg_1_2_c.STL" file="./meshes/dg5f_right/collision/rl_dg_1_2_c.STL" />
    <mesh name="rl_dg_1_3_c.STL" file="./meshes/dg5f_right/collision/rl_dg_1_3_c.STL" />
    <mesh name="rl_dg_1_4_c.STL" file="./meshes/dg5f_right/collision/rl_dg_1_4_c.STL" />
    <mesh name="rl_dg_1_tip_c.STL" file="./meshes/dg5f_right/collision/rl_dg_1_tip_c.STL" />
    <mesh name="rl_dg_2_1_c.STL" file="./meshes/dg5f_right/collision/rl_dg_2_1_c.STL" />
    <mesh name="rl_dg_2_2_c.STL" file="./meshes/dg5f_right/collision/rl_dg_2_2_c.STL" />
    <mesh name="rl_dg_2_3_c.STL" file="./meshes/dg5f_right/collision/rl_dg_2_3_c.STL" />
    <mesh name="rl_dg_2_4_c.STL" file="./meshes/dg5f_right/collision/rl_dg_2_4_c.STL" />
    <mesh name="rl_dg_2_tip_c.STL" file="./meshes/dg5f_right/collision/rl_dg_2_tip_c.STL" />
    <mesh name="rl_dg_3_1_c.STL" file="./meshes/dg5f_right/collision/rl_dg_3_1_c.STL" />
    <mesh name="rl_dg_3_2_c.STL" file="./meshes/dg5f_right/collision/rl_dg_3_2_c.STL" />
    <mesh name="rl_dg_3_3_c.STL" file="./meshes/dg5f_right/collision/rl_dg_3_3_c.STL" />
    <mesh name="rl_dg_3_4_c.STL" file="./meshes/dg5f_right/collision/rl_dg_3_4_c.STL" />
    <mesh name="rl_dg_3_tip_c.STL" file="./meshes/dg5f_right/collision/rl_dg_3_tip_c.STL" />
    <mesh name="rl_dg_4_1_c.STL" file="./meshes/dg5f_right/collision/rl_dg_4_1_c.STL" />
    <mesh name="rl_dg_4_2_c.STL" file="./meshes/dg5f_right/collision/rl_dg_4_2_c.STL" />
    <mesh name="rl_dg_4_3_c.STL" file="./meshes/dg5f_right/collision/rl_dg_4_3_c.STL" />
    <mesh name="rl_dg_4_4_c.STL" file="./meshes/dg5f_right/collision/rl_dg_4_4_c.STL" />
    <mesh name="rl_dg_4_tip_c.STL" file="./meshes/dg5f_right/collision/rl_dg_4_tip_c.STL" />
    <mesh name="rl_dg_5_1_c.STL" file="./meshes/dg5f_right/collision/rl_dg_5_1_c.STL" />
    <mesh name="rl_dg_5_2_c.STL" file="./meshes/dg5f_right/collision/rl_dg_5_2_c.STL" />
    <mesh name="rl_dg_5_3_c.STL" file="./meshes/dg5f_right/collision/rl_dg_5_3_c.STL" />
    <mesh name="rl_dg_5_4_c.STL" file="./meshes/dg5f_right/collision/rl_dg_5_4_c.STL" />
    <mesh name="rl_dg_5_tip_c.STL" file="./meshes/dg5f_right/collision/rl_dg_5_tip_c.STL" />
  </asset>

  <worldbody>
    <!-- LEFT ARM -->
    <body name="panda_left_link0" pos="0.45 -0.5 0.6" quat="0.154 0 0 -0.988" childclass="robot">
      <geom name="panda_left_link0_collision" pos="0 0 0" quat="1 0 0 0" type="mesh" mesh="link0.stl" class="left-collision" />
      <body name="panda_left_link1" pos="0 0 0.333" quat="1.0 0.0 0.0 0.0">
        <joint name="panda_left_joint1" type="hinge" ref="0.0" class="motor" range="-2.8973 2.8973" axis="0 0 1" />
        <inertial pos="0.003875 0.002081 -0.04762" quat="1.0 0.0 0.0 0.0" mass="4.970684" diaginertia="0.70337 0.70661 0.009117" />
        <geom name="panda_left_link1_collision" pos="0 0 0" quat="1 0 0 0" type="mesh" mesh="link1.stl" class="left-collision" />
        <body name="panda_left_link2" pos="0 0 0" quat="0.7071067811865476 -0.7071067811865475 0.0 0.0">
          <joint name="panda_left_joint2" type="hinge" ref="0.0" class="motor" range="-1.7628 1.7628" axis="0 0 1" />
          <inertial pos="-0.003141 -0.02872  0.003495" quat="1.0 0.0 0.0 0.0" mass="0.646926" diaginertia="0.007962 0.02811 0.025995" />
          <geom name="panda_left_link2_collision" pos="0 0 0" quat="1 0 0 0" type="mesh" mesh="link2.stl" class="left-collision" />
          <body name="panda_left_link3" pos="0 -0.316 0" quat="0.7071067811865476 0.7071067811865475 0.0 0.0">
            <joint name="panda_left_joint3" type="hinge" ref="0.0" class="motor" range="-2.8973 2.8973" axis="0 0 1" />
            <inertial pos="2.7518e-02 3.9252e-02 -6.6502e-02" quat="1.0 0.0 0.0 0.0" mass="3.228604" diaginertia="0.037242 0.036155 0.01083" />
            <geom name="panda_left_link3_collision" pos="0 0 0" quat="1 0 0 0" type="mesh" mesh="link3.stl" class="left-collision" />
            <body name="panda_left_link4" pos="0.0825 0 0" quat="0.7071067811865476 0.7071067811865475 0.0 0.0">
              <joint name="panda_left_joint4" type="hinge" ref="0.0" class="motor" range="-3.0718 -0.0698" axis="0 0 1" />
              <inertial pos="-5.317e-02 1.04419e-01 2.7454e-02" quat="1.0 0.0 0.0 0.0" mass="3.587895" diaginertia="0.025853 0.019552 0.028323" />
              <geom name="panda_left_link4_collision" pos="0 0 0" quat="1 0 0 0" type="mesh" mesh="link4.stl" class="left-collision" />
              <body name="panda_left_link5" pos="-0.0825 0.384 0" quat="0.7071067811865476 -0.7071067811865475 0.0 0.0">
                <joint name="panda_left_joint5" type="hinge" ref="0.0" class="motor" range="-2.8973 2.8973" axis="0 0 1" />
                <inertial pos="-1.1953e-02 4.1065e-02 -3.8437e-02" quat="1.0 0.0 0.0 0.0" mass="1.225946" diaginertia="0.035549 0.029474 0.008627" />
                <geom name="panda_left_link5_collision" pos="0 0 0" quat="1 0 0 0" type="mesh" mesh="link5.stl" class="left-collision" />
                <body name="panda_left_link6" pos="0 0 0" quat="0.7071067811865476 0.7071067811865475 0.0 0.0">
                  <joint name="panda_left_joint6" type="hinge" ref="0.0" class="motor" range="-0.0175 3.7525" axis="0 0 1" />
                  <inertial pos="6.0149e-02 -1.4117e-02 -1.0517e-02" quat="1.0 0.0 0.0 0.0" mass="1.666555" diaginertia="0.001964 0.004354 0.005433" />
                  <geom name="panda_left_link6_collision" pos="0 0 0" quat="1 0 0 0" type="mesh" mesh="link6.stl" class="left-collision" />
                  <body name="panda_left_link7" pos="0.088 0 0" quat="0.7071067811865476 0.7071067811865475 0.0 0.0">
                    <joint name="panda_left_joint7" type="hinge" ref="0.0" class="motor" range="-2.8973 2.8973" axis="0 0 1" />
                    <inertial pos="1.0517e-02 -4.252e-03 6.1597e-02" quat="1.0 0.0 0.0 0.0" mass="0.735522" diaginertia="0.012516 0.010027 0.004815" />
                    <geom name="panda_left_link7_collision" pos="0 0 0" quat="1 0 0 0" type="mesh" mesh="link7.stl" class="left-collision" />
                    <body name="panda_left_link8" pos="0 0 0.000" quat="1.0 0.0 0.0 0.0">
                      <body name="ll_dg_mount" pos="0 0 0.1034" quat="0.9689124217106447 0.0 0.0 -0.24740395925452294">
                        <inertial pos="6.4721E-09 2.1674E-05 0.0049997" quat="1.0 0.0 0.0 0.0" mass="0.05" diaginertia="1.0999e-05 1.1018e-05 2.0531e-05" />
                        <geom name="ll_dg_mount_collision" pos="0 0 0" quat="1 0 0 0" type="mesh" mesh="ll_dg_mount_c.STL" class="left-collision" />
                        <body name="ll_dg_base" pos="0 0 0.004" quat="1.0 0.0 0.0 0.0">
                          <inertial pos="-0.00058969 -0.00051381 0.037363" quat="1.0 0.0 0.0 0.0" mass="0.45" diaginertia="0.00048608 0.00049085 0.00043369" />
                          <geom name="ll_dg_base_collision" pos="0 0 0" quat="1.0 0.0 0.0 0.0" type="mesh" mesh="ll_dg_base_c.STL" class="left-collision" />
                          <body name="ll_dg_palm" pos="0 0 0.0698" quat="1.0 0.0 0.0 0.0">
                          <body name="left_palm_site" pos="0 0 0.02" quat="-0.5 -0.5 0.5 0.5">
                            <site name="left_palm_site" group="2" size="0.002 0.002 0.002"/>
                          </body>
                            <inertial pos="-0.0089544 -0.00095674 0.041327" quat="1.0 0.0 0.0 0.0" mass="0.35" diaginertia="0.00052648 0.00041644 0.00045776" />
                            <geom name="ll_dg_palm_collision" pos="0 0 0" quat="1.0 0.0 0.0 0.0" type="mesh" mesh="ll_dg_palm_c.STL" class="left-collision" />
                            <body name="ll_dg_1_1" pos="-0.0162 -0.019 0.0128" quat="1.0 0.0 0.0 0.0">
                              <joint name="lj_dg_1_1" type="hinge" ref="0.0" class="motor" range="-0.8901179185171081 0.3839724354387525" axis="1 0 0" />
                              <inertial pos="0.021473 3.1163E-06 0.0028146" quat="1.0 0.0 0.0 0.0" mass="0.045" diaginertia="4.2707e-06 1.3718e-05 1.2161e-05" />
                              <geom name="ll_dg_1_1_collision" pos="0 0 0" quat="1.0 0.0 0.0 0.0" type="mesh" mesh="ll_dg_1_1_c.STL" class="left-collision" />
                              <body name="ll_dg_1_2" pos="0.04195 0.0 0.0" quat="1.0 0.0 0.0 0.0">
                                <joint name="lj_dg_1_2" type="hinge" ref="0.0" class="motor" range="-0.0 3.141592653589793" axis="0 0 1" />
                                <inertial pos="-0.00055633 -0.0155 0.00055633" quat="1.0 0.0 0.0 0.0" mass="0.025" diaginertia="1.9935e-06 1.459e-06 1.9935e-06" />
                                <geom name="ll_dg_1_2_collision" pos="0 0 0" quat="1.0 0.0 0.0 0.0" type="mesh" mesh="ll_dg_1_2_c.STL" class="left-collision" />
                                <body name="ll_dg_1_3" pos="0.0 -0.031 0.0" quat="1.0 0.0 0.0 0.0">
                                  <joint name="lj_dg_1_3" type="hinge" ref="0.0" class="motor" range="-1.5707963267948966 1.5707963267948966" axis="1 0 0" />
                                  <inertial pos="-2.3008E-05 -0.014842 4.7446E-06" quat="1.0 0.0 0.0 0.0" mass="0.045" diaginertia="5.9794e-06 2.458e-06 6.4181e-06" />
                                  <geom name="ll_dg_1_3_collision" pos="0 0 0" quat="1.0 0.0 0.0 0.0" type="mesh" mesh="ll_dg_1_3_c.STL" class="left-collision" />
                                  <body name="ll_dg_1_4" pos="0.0 -0.0388 0.0" quat="1.0 0.0 0.0 0.0">
                                    <joint name="lj_dg_1_4" type="hinge" ref="0.0" class="motor" range="-1.5707963267948966 1.5707963267948966" axis="1 0 0" />
                                    <inertial pos="0.00020482 -0.018795 -0.00036539" quat="1.0 0.0 0.0 0.0" mass="0.045" diaginertia="9.4915e-06 2.9391e-06 9.8194e-06" />
                                    <geom name="ll_dg_1_4_collision" pos="0 0 0" quat="1.0 0.0 0.0 0.0" type="mesh" mesh="ll_dg_1_4_c.STL" class="left-collision" />
                                    <body name="ll_dg_1_tip" pos="0.0 -0.0363 0.0" quat="1.0 0.0 0.0 0.0">
                                      <body name="left_thumb_tip_site" pos="0 0 0" quat="1 0 0 0">
                                        <site name="left_thumb_tip_site" group="2" size="0.002 0.002 0.002"/>
                                      </body>
                                      <inertial pos="-5.479E-07 -0.007157 0.0038063" quat="1.0 0.0 0.0 0.0" mass="0.005" diaginertia="1.9895e-07 2.5698e-07 3.2445e-07" />
                                      <geom name="ll_dg_1_tip_collision" pos="0 0 0" quat="1.0 0.0 0.0 0.0" type="mesh" mesh="ll_dg_1_tip_c.STL" class="left-collision" />
                                    </body>
                                  </body>
                                </body>
                              </body>
                            </body>
                            <body name="ll_dg_2_1" pos="-0.0071 -0.027 0.0661" quat="1.0 0.0 0.0 0.0">
                              <joint name="lj_dg_2_1" type="hinge" ref="0.0" class="motor" range="-0.6108652381980153 0.4188790204786391" axis="1 0 0" />
                              <inertial pos="0.0010606 -0.00058566 0.023499" quat="1.0 0.0 0.0 0.0" mass="0.045" diaginertia="6.5541e-06 9.5306e-06 7.0879e-06" />
                              <geom name="ll_dg_2_1_collision" pos="0 0 0" quat="1.0 0.0 0.0 0.0" type="mesh" mesh="ll_dg_2_1_c.STL" class="left-collision" />
                              <body name="ll_dg_2_2" pos="0.01765 0.0 0.0265" quat="1.0 0.0 0.0 0.0">
                                <joint name="lj_dg_2_2" type="hinge" ref="0.0" class="motor" range="-0.0 2.007128639793479" axis="0 1 0" />
                                <inertial pos="-4.7446E-06 2.3008E-05 0.023958" quat="1.0 0.0 0.0 0.0" mass="0.045" diaginertia="6.4181e-06 5.9794e-06 2.458e-06" />
                                <geom name="ll_dg_2_2_collision" pos="0 0 0" quat="1.0 0.0 0.0 0.0" type="mesh" mesh="ll_dg_2_2_c.STL" class="left-collision" />
                                <body name="ll_dg_2_3" pos="0.0 0.0 0.0388" quat="1.0 0.0 0.0 0.0">
                                  <joint name="lj_dg_2_3" type="hinge" ref="0.0" class="motor" range="-1.5707963267948966 1.5707963267948966" axis="0 1 0" />
                                  <inertial pos="-4.7446E-06 2.3008E-05 0.023958" quat="1.0 0.0 0.0 0.0" mass="0.045" diaginertia="6.4181e-06 5.9794e-06 2.458e-06" />
                                  <geom name="ll_dg_2_3_collision" pos="0 0 0" quat="1.0 0.0 0.0 0.0" type="mesh" mesh="ll_dg_2_3_c.STL" class="left-collision" />
                                  <body name="ll_dg_2_4" pos="0.0 0.0 0.0388" quat="1.0 0.0 0.0 0.0">
                                    <joint name="lj_dg_2_4" type="hinge" ref="0.0" class="motor" range="-1.5707963267948966 1.5707963267948966" axis="0 1 0" />
                                    <inertial pos="-0.00070816 0.00043036 0.017842" quat="1.0 0.0 0.0 0.0" mass="0.025" diaginertia="2.8592e-06 2.3907e-06 1.6592e-06" />
                                    <geom name="ll_dg_2_4_collision" pos="0 0 0" quat="1.0 0.0 0.0 0.0" type="mesh" mesh="ll_dg_2_4_c.STL" class="left-collision" />
                                    <body name="ll_dg_2_tip" pos="0.0 0.0 0.0255" quat="1.0 0.0 0.0 0.0">
                                    <body name="left_index_tip_site" pos="0 0 0" quat="1 0 0 0">
                                      <site name="left_index_tip_site" group="2" size="0.002 0.002 0.002"/>
                                    </body>
                                      <inertial pos="0.0038063 5.479E-07 0.007157" quat="1.0 0.0 0.0 0.0" mass="0.005" diaginertia="3.2445e-07 1.9895e-07 2.5698e-07" />
                                      <geom name="ll_dg_2_tip_collision" pos="0 0 0" quat="1.0 0.0 0.0 0.0" type="mesh" mesh="ll_dg_2_tip_c.STL" class="left-collision" />
                                    </body>
                                  </body>
                                </body>
                              </body>
                            </body>
                            <body name="ll_dg_3_1" pos="-0.0071 -0.0025 0.0701" quat="1.0 0.0 0.0 0.0">
                              <joint name="lj_dg_3_1" type="hinge" ref="0.0" class="motor" range="-0.6108652381980153 0.6108652381980153" axis="1 0 0" />
                              <inertial pos="0.0012558 -0.00017703 0.023374" quat="1.0 0.0 0.0 0.0" mass="0.045" diaginertia="6.233e-06 9.3331e-06 6.7817e-06" />
                              <geom name="ll_dg_3_1_collision" pos="0 0 0" quat="1.0 0.0 0.0 0.0" type="mesh" mesh="ll_dg_3_1_c.STL" class="left-collision" />
                              <body name="ll_dg_3_2" pos="0.01765 0.0 0.0265" quat="1.0 0.0 0.0 0.0">
                                <joint name="lj_dg_3_2" type="hinge" ref="0.0" class="motor" range="0.0 1.9547687622336491" axis="0 1 0" />
                                <inertial pos="-4.7446E-06 2.3008E-05 0.023958" quat="1.0 0.0 0.0 0.0" mass="0.045" diaginertia="6.4181e-06 5.9794e-06 2.458e-06" />
                                <geom name="ll_dg_3_2_collision" pos="0 0 0" quat="1.0 0.0 0.0 0.0" type="mesh" mesh="ll_dg_3_2_c.STL" class="left-collision" />
                                <body name="ll_dg_3_3" pos="0.0 0.0 0.0388" quat="1.0 0.0 0.0 0.0">
                                  <joint name="lj_dg_3_3" type="hinge" ref="0.0" class="motor" range="-1.5707963267948966 1.5707963267948966" axis="0 1 0" />
                                  <inertial pos="-4.7446E-06 2.3008E-05 0.023958" quat="1.0 0.0 0.0 0.0" mass="0.045" diaginertia="6.4181e-06 5.9794e-06 2.458e-06" />
                                  <geom name="ll_dg_3_3_collision" pos="0 0 0" quat="1.0 0.0 0.0 0.0" type="mesh" mesh="ll_dg_3_3_c.STL" class="left-collision" />
                                  <body name="ll_dg_3_4" pos="0.0 0.0 0.0388" quat="1.0 0.0 0.0 0.0">
                                    <joint name="lj_dg_3_4" type="hinge" ref="0.0" class="motor" range="-1.5707963267948966 1.5707963267948966" axis="0 1 0" />
                                    <inertial pos="-0.00070816 0.00043036 0.017842" quat="1.0 0.0 0.0 0.0" mass="0.025" diaginertia="2.8592e-06 2.3907e-06 1.6592e-06" />
                                    <geom name="ll_dg_3_4_collision" pos="0 0 0" quat="1.0 0.0 0.0 0.0" type="mesh" mesh="ll_dg_3_4_c.STL" class="left-collision" />
                                    <body name="ll_dg_3_tip" pos="0.0 0.0 0.0255" quat="1.0 0.0 0.0 0.0">
                                      <body name="left_middle_tip_site" pos="0 0 0" quat="1 0 0 0">
                                        <site name="left_middle_tip_site" group="2" size="0.002 0.002 0.002"/>
                                      </body>
                                      <inertial pos="0.0038063 5.479E-07 0.007157" quat="1.0 0.0 0.0 0.0" mass="0.005" diaginertia="3.2445e-07 1.9895e-07 2.5698e-07" />
                                      <geom name="ll_dg_3_tip_collision" pos="0 0 0" quat="1.0 0.0 0.0 0.0" type="mesh" mesh="ll_dg_3_tip_c.STL" class="left-collision" />
                                    </body>
                                  </body>
                                </body>
                              </body>
                            </body>
                            <body name="ll_dg_4_1" pos="-0.0071 0.022 0.0621" quat="1.0 0.0 0.0 0.0">
                              <joint name="lj_dg_4_1" type="hinge" ref="0.0" class="motor" range="-0.4188790204786391 0.6108652381980153" axis="1 0 0" />
                              <inertial pos="0.001061 0.00024417 0.023499" quat="1.0 0.0 0.0 0.0" mass="0.045" diaginertia="6.5538e-06 9.5305e-06 7.0877e-06" />
                              <geom name="ll_dg_4_1_collision" pos="0 0 0" quat="1.0 0.0 0.0 0.0" type="mesh" mesh="ll_dg_4_1_c.STL" class="left-collision" />
                              <body name="ll_dg_4_2" pos="0.01765 0.0 0.0265" quat="1.0 0.0 0.0 0.0">
                                <joint name="lj_dg_4_2" type="hinge" ref="0.0" class="motor" range="0.0 1.9024088846738192" axis="0 1 0" />
                                <inertial pos="-4.7446E-06 2.3008E-05 0.023958" quat="1.0 0.0 0.0 0.0" mass="0.045" diaginertia="6.4181e-06 5.9794e-06 2.458e-06" />
                                <geom name="ll_dg_4_2_collision" pos="0 0 0" quat="1.0 0.0 0.0 0.0" type="mesh" mesh="ll_dg_4_2_c.STL" class="left-collision" />
                                <body name="ll_dg_4_3" pos="0.0 0.0 0.0388" quat="1.0 0.0 0.0 0.0">
                                  <joint name="lj_dg_4_3" type="hinge" ref="0.0" class="motor" range="-1.5707963267948966 1.5707963267948966" axis="0 1 0" />
                                  <inertial pos="-4.7446E-06 2.3008E-05 0.023958" quat="1.0 0.0 0.0 0.0" mass="0.045" diaginertia="6.4181e-06 5.9794e-06 2.458e-06" />
                                  <geom name="ll_dg_4_3_collision" pos="0 0 0" quat="1.0 0.0 0.0 0.0" type="mesh" mesh="ll_dg_4_3_c.STL" class="left-collision" />
                                  <body name="ll_dg_4_4" pos="0.0 0.0 0.0388" quat="1.0 0.0 0.0 0.0">
                                    <joint name="lj_dg_4_4" type="hinge" ref="0.0" class="motor" range="-1.5707963267948966 1.5707963267948966" axis="0 1 0" />
                                    <inertial pos="-0.00070816 0.00043036 0.017842" quat="1.0 0.0 0.0 0.0" mass="0.025" diaginertia="2.8592e-06 2.3907e-06 1.6592e-06" />
                                    <geom name="ll_dg_4_4_collision" pos="0 0 0" quat="1.0 0.0 0.0 0.0" type="mesh" mesh="ll_dg_4_4_c.STL" class="left-collision" />
                                    <body name="ll_dg_4_tip" pos="0.0 0.0 0.0255" quat="1.0 0.0 0.0 0.0">
                                      <body name="left_ring_tip_site" pos="0 0 0" quat="1 0 0 0">
                                        <site name="left_ring_tip_site" group="2" size="0.002 0.002 0.002"/>
                                      </body>
                                      <inertial pos="0.0038063 5.479E-07 0.007157" quat="1.0 0.0 0.0 0.0" mass="0.005" diaginertia="3.2445e-07 1.9895e-07 2.5698e-07" />
                                      <geom name="ll_dg_4_tip_collision" pos="0 0 0" quat="1.0 0.0 0.0 0.0" type="mesh" mesh="ll_dg_4_tip_c.STL" class="left-collision" />
                                    </body>
                                  </body>
                                </body>
                              </body>
                            </body>
                            <body name="ll_dg_5_1" pos="0.0103 0.0195 0.0182" quat="1.0 0.0 0.0 0.0">
                              <joint name="lj_dg_5_1" type="hinge" ref="0.0" class="motor" range="-1.0471975511965976 0.017453292519943295" axis="0 0 1" />
                              <inertial pos="-0.0045287 0.025016 0.014025" quat="1.0 0.0 0.0 0.0" mass="0.055" diaginertia="2.3621e-05 2.3655e-05 1.1298e-05" />
                              <geom name="ll_dg_5_1_collision" pos="0 0 0" quat="1.0 0.0 0.0 0.0" type="mesh" mesh="ll_dg_5_1_c.STL" class="left-collision" />
                              <body name="ll_dg_5_2" pos="0.0 0.028 0.0381" quat="1.0 0.0 0.0 0.0">
                                <joint name="lj_dg_5_2" type="hinge" ref="0.0" class="motor" range="-0.6108652381980153 0.4188790204786391" axis="1 0 0" />
                                <inertial pos="0.00055633 0.00055633 0.0155" quat="1.0 0.0 0.0 0.0" mass="0.025" diaginertia="1.9935e-06 1.9935e-06 1.459e-06" />
                                <geom name="ll_dg_5_2_collision" pos="0 0 0" quat="1.0 0.0 0.0 0.0" type="mesh" mesh="ll_dg_5_2_c.STL" class="left-collision" />
                                <body name="ll_dg_5_3" pos="0.0 0.0 0.031" quat="1.0 0.0 0.0 0.0">
                                  <joint name="lj_dg_5_3" type="hinge" ref="0.0" class="motor" range="-1.5707963267948966 1.5707963267948966" axis="0 1 0" />
                                  <inertial pos="4.7446E-06 2.3008E-05 0.014842" quat="1.0 0.0 0.0 0.0" mass="0.045" diaginertia="6.4181e-06 5.9794e-06 2.458e-06" />
                                  <geom name="ll_dg_5_3_collision" pos="0 0 0" quat="1.0 0.0 0.0 0.0" type="mesh" mesh="ll_dg_5_3_c.STL" class="left-collision" />
                                  <body name="ll_dg_5_4" pos="0.0 0.0 0.0388" quat="1.0 0.0 0.0 0.0">
                                    <joint name="lj_dg_5_4" type="hinge" ref="0.0" class="motor" range="-1.5707963267948966 1.5707963267948966" axis="0 1 0" />
                                    <inertial pos="-0.00036539 -0.00020482 0.018795" quat="1.0 0.0 0.0 0.0" mass="0.045" diaginertia="9.8194e-06 9.4915e-06 2.9391e-06" />
                                    <geom name="ll_dg_5_4_collision" pos="0 0 0" quat="1.0 0.0 0.0 0.0" type="mesh" mesh="ll_dg_5_4_c.STL" class="left-collision" />
                                    <body name="ll_dg_5_tip" pos="0.0 0.0 0.0363" quat="1.0 0.0 0.0 0.0">
                                      <body name="left_pinky_tip_site" pos="0 0 0" quat="1 0 0 0">
                                        <site name="left_pinky_tip_site" group="2" rgba="0 0 1 1" size="0.002 0.002 0.002"/>
                                      </body>
                                      <inertial pos="0.0038063 5.479E-07 0.007157" quat="1.0 0.0 0.0 0.0" mass="0.005" diaginertia="3.2445e-07 1.9895e-07 2.5698e-07" />
                                      <geom name="ll_dg_5_tip_collision" pos="0 0 0" quat="1.0 0.0 0.0 0.0" type="mesh" mesh="ll_dg_5_tip_c.STL" class="left-collision" />
                                    </body>
                                  </body>
                                </body>
                              </body>
                            </body>
                          </body>
                        </body>
                      </body>
                    </body>
                  </body>
                </body>
              </body>
            </body>
          </body>
        </body>
      </body>
    </body> 
    <!-- RIGHT ARM -->
    <body name="panda_right_link0" pos="-0.45 -0.5 0.6" quat="0.988 0.0 0.0 -0.154" childclass="robot">
      <geom name="panda_right_link0_collision" pos="0 0 0" quat="1 0 0 0" type="mesh" mesh="link0.stl" class="collision" />
      <body name="panda_right_link1" pos="0 0 0.333" quat="1.0 0.0 0.0 0.0">
        <joint name="panda_right_joint1" type="hinge" ref="0.0" class="motor" range="-2.8973 2.8973" axis="0 0 1" />
        <inertial pos="0.003875 0.002081 -0.04762" quat="1.0 0.0 0.0 0.0" mass="4.970684" diaginertia="0.70337 0.70661 0.009117" />
        <geom name="panda_right_link1_collision" pos="0 0 0" quat="1 0 0 0" type="mesh" mesh="link1.stl" class="collision" />
        <body name="panda_right_link2" pos="0 0 0" quat="0.7071067811865476 -0.7071067811865475 0.0 0.0">
          <joint name="panda_right_joint2" type="hinge" ref="0.0" class="motor" range="-1.7628 1.7628" axis="0 0 1" />
          <inertial pos="-0.003141 -0.02872  0.003495" quat="1.0 0.0 0.0 0.0" mass="0.646926" diaginertia="0.007962 0.02811 0.025995" />
          <geom name="panda_right_link2_collision" pos="0 0 0" quat="1 0 0 0" type="mesh" mesh="link2.stl" class="collision" />
          <body name="panda_right_link3" pos="0 -0.316 0" quat="0.7071067811865476 0.7071067811865475 0.0 0.0">
            <joint name="panda_right_joint3" type="hinge" ref="0.0" class="motor" range="-2.8973 2.8973" axis="0 0 1" />
            <inertial pos="2.7518e-02 3.9252e-02 -6.6502e-02" quat="1.0 0.0 0.0 0.0" mass="3.228604" diaginertia="0.037242 0.036155 0.01083" />
            <geom name="panda_right_link3_collision" pos="0 0 0" quat="1 0 0 0" type="mesh" mesh="link3.stl" class="collision" />
            <body name="panda_right_link4" pos="0.0825 0 0" quat="0.7071067811865476 0.7071067811865475 0.0 0.0">
              <joint name="panda_right_joint4" type="hinge" ref="0.0" class="motor" range="-3.0718 -0.0698" axis="0 0 1" />
              <inertial pos="-5.317e-02 1.04419e-01 2.7454e-02" quat="1.0 0.0 0.0 0.0" mass="3.587895" diaginertia="0.025853 0.019552 0.028323" />
              <geom name="panda_right_link4_collision" pos="0 0 0" quat="1 0 0 0" type="mesh" mesh="link4.stl" class="collision" />
              <body name="panda_right_link5" pos="-0.0825 0.384 0" quat="0.7071067811865476 -0.7071067811865475 0.0 0.0">
                <joint name="panda_right_joint5" type="hinge" ref="0.0" class="motor" range="-2.8973 2.8973" axis="0 0 1" />
                <inertial pos="-1.1953e-02 4.1065e-02 -3.8437e-02" quat="1.0 0.0 0.0 0.0" mass="1.225946" diaginertia="0.035549 0.029474 0.008627" />
                <geom name="panda_right_link5_collision" pos="0 0 0" quat="1 0 0 0" type="mesh" mesh="link5.stl" class="collision" />
                <body name="panda_right_link6" pos="0 0 0" quat="0.7071067811865476 0.7071067811865475 0.0 0.0">
                  <joint name="panda_right_joint6" type="hinge" ref="0.0" class="motor" range="-0.0175 3.7525" axis="0 0 1" />
                  <inertial pos="6.0149e-02 -1.4117e-02 -1.0517e-02" quat="1.0 0.0 0.0 0.0" mass="1.666555" diaginertia="0.001964 0.004354 0.005433" />
                  <geom name="panda_right_link6_collision" pos="0 0 0" quat="1 0 0 0" type="mesh" mesh="link6.stl" class="collision" />
                  <body name="panda_right_link7" pos="0.088 0 0" quat="0.7071067811865476 0.7071067811865475 0.0 0.0">
                    <joint name="panda_right_joint7" type="hinge" ref="0.0" class="motor" range="-2.8973 2.8973" axis="0 0 1" />
                    <inertial pos="1.0517e-02 -4.252e-03 6.1597e-02" quat="1.0 0.0 0.0 0.0" mass="0.735522" diaginertia="0.012516 0.010027 0.004815" />
                    <geom name="panda_right_link7_collision" pos="0 0 0" quat="1 0 0 0" type="mesh" mesh="link7.stl" class="collision" />
                    <body name="panda_right_link8" pos="0 0 0.000" quat="1.0 0.0 0.0 0.0">
                      <body name="rl_dg_mount" pos="0 0 0.1034" quat="0.9689124217106447 0.0 0.0 -0.24740395925452294">
                        <inertial pos="-6.4721E-09 -2.1674E-05 0.0049997" quat="1.0 0.0 0.0 0.0" mass="0.05" diaginertia="1.0999e-05 1.1018e-05 2.0531e-05" />
                        <geom name="rl_dg_mount_collision" pos="0 0 0" quat="1 0 0 0" type="mesh" mesh="rl_dg_mount_c.STL" class="collision" />
                        <body name="rl_dg_base" pos="0 0 0.004" quat="1.0 0.0 0.0 0.0">
                          <inertial pos="-0.00058969 0.0005138 0.037363" quat="1.0 0.0 0.0 0.0" mass="0.45" diaginertia="0.00048608 0.00049085 0.00043369" />
                          <geom name="rl_dg_base_collision" pos="0 0 0" quat="1.0 0.0 0.0 0.0" type="mesh" mesh="rl_dg_base_c.STL" class="collision" />
                          <body name="rl_dg_palm" pos="0 0 0.0698" quat="1.0 0.0 0.0 0.0">
                            <body name="right_palm_site" pos="0 0 0.02" quat="-0.5 -0.5 0.5 0.5">
                              <site name="right_palm_site" group="2" size="0.002 0.002 0.002"/>
                            </body>
                            <inertial pos="-0.0089577 0.00095577 0.041325" quat="1.0 0.0 0.0 0.0" mass="0.35" diaginertia="0.00052656 0.00041654 0.00045783" />
                            <geom name="rl_dg_palm_collision" pos="0 0 0" quat="1.0 0.0 0.0 0.0" type="mesh" mesh="rl_dg_palm_c.STL" class="collision" />
                            <body name="rl_dg_1_1" pos="-0.0162 0.019 0.0128" quat="1.0 0.0 0.0 0.0">
                              <joint name="rj_dg_1_1" type="hinge" ref="0.0" class="motor" range="-0.3839724354387525 0.8901179185171081" axis="1 0 0" />
                              <inertial pos="0.021473 3.1163E-06 0.0028146" quat="1.0 0.0 0.0 0.0" mass="0.045" diaginertia="4.2707e-06 1.3718e-05 1.2161e-05" />
                              <geom name="rl_dg_1_1_collision" pos="0 0 0" quat="1.0 0.0 0.0 0.0" type="mesh" mesh="rl_dg_1_1_c.STL" class="collision" />
                              <body name="rl_dg_1_2" pos="0.04195 0.0 0.0" quat="1.0 0.0 0.0 0.0">
                                <joint name="rj_dg_1_2" type="hinge" ref="0.0" class="motor" range="-3.141592653589793 0.0" axis="0 0 1" />
                                <inertial pos="0.00055633 0.0155 0.00055633" quat="1.0 0.0 0.0 0.0" mass="0.025" diaginertia="1.9935e-06 1.459e-06 1.9935e-06" />
                                <geom name="rl_dg_1_2_collision" pos="0 0 0" quat="1.0 0.0 0.0 0.0" type="mesh" mesh="rl_dg_1_2_c.STL" class="collision" />
                                <body name="rl_dg_1_3" pos="0.0 0.031 0.0" quat="1.0 0.0 0.0 0.0">
                                  <joint name="rj_dg_1_3" type="hinge" ref="0.0" class="motor" range="-1.5707963267948966 1.5707963267948966" axis="1 0 0" />
                                  <inertial pos="2.3008E-05 0.014842 4.7446E-06" quat="1.0 0.0 0.0 0.0" mass="0.045" diaginertia="5.9794e-06 2.458e-06 6.4181e-06" />
                                  <geom name="rl_dg_1_3_collision" pos="0 0 0" quat="1.0 0.0 0.0 0.0" type="mesh" mesh="rl_dg_1_3_c.STL" class="collision" />
                                  <body name="rl_dg_1_4" pos="0.0 0.0388 0.0" quat="1.0 0.0 0.0 0.0">
                                    <joint name="rj_dg_1_4" type="hinge" ref="0.0" class="motor" range="-1.5707963267948966 1.5707963267948966" axis="1 0 0" />
                                    <inertial pos="-0.00020482 0.018795 -0.00036539" quat="1.0 0.0 0.0 0.0" mass="0.045" diaginertia="9.4915e-06 2.9391e-06 9.8194e-06" />
                                    <geom name="rl_dg_1_4_collision" pos="0 0 0" quat="1.0 0.0 0.0 0.0" type="mesh" mesh="rl_dg_1_4_c.STL" class="collision" />
                                    <body name="rl_dg_1_tip" pos="0.0 0.0363 0.0" quat="1.0 0.0 0.0 0.0">
                                      <body name="right_thumb_tip_site" pos="0 0 0" quat="1 0 0 0">
                                        <site name="right_thumb_tip_site" group="2" size="0.002 0.002 0.002"/>
                                      </body>
                                      <inertial pos="5.479E-07 0.007157 0.0038063" quat="1.0 0.0 0.0 0.0" mass="0.005" diaginertia="1.9895e-07 2.5698e-07 3.2445e-07" />
                                      <geom name="rl_dg_1_tip_collision" pos="0 0 0" quat="1.0 0.0 0.0 0.0" type="mesh" mesh="rl_dg_1_tip_c.STL" class="collision" />
                                    </body>
                                  </body>
                                </body>
                              </body>
                            </body>
                            <body name="rl_dg_2_1" pos="-0.0071 0.027 0.0661" quat="1.0 0.0 0.0 0.0">
                              <joint name="rj_dg_2_1" type="hinge" ref="0.0" class="motor" range="-0.4188790204786391 0.6108652381980153" axis="1 0 0" />
                              <inertial pos="0.001061 0.00024417 0.023499" quat="1.0 0.0 0.0 0.0" mass="0.045" diaginertia="6.5538e-06 9.5305e-06 7.0877e-06" />
                              <geom name="rl_dg_2_1_collision" pos="0 0 0" quat="1.0 0.0 0.0 0.0" type="mesh" mesh="rl_dg_2_1_c.STL" class="collision" />
                              <body name="rl_dg_2_2" pos="0.01765 0.0 0.0265" quat="1.0 0.0 0.0 0.0">
                                <joint name="rj_dg_2_2" type="hinge" ref="0.0" class="motor" range="-0.0 2.007128639793479" axis="0 1 0" />
                                <inertial pos="-4.7446E-06 2.3008E-05 0.023958" quat="1.0 0.0 0.0 0.0" mass="0.045" diaginertia="6.4181e-06 5.9794e-06 2.458e-06" />
                                <geom name="rl_dg_2_2_collision" pos="0 0 0" quat="1.0 0.0 0.0 0.0" type="mesh" mesh="rl_dg_2_2_c.STL" class="collision" />
                                <body name="rl_dg_2_3" pos="0.0 0.0 0.0388" quat="1.0 0.0 0.0 0.0">
                                  <joint name="rj_dg_2_3" type="hinge" ref="0.0" class="motor" range="-1.5707963267948966 1.5707963267948966" axis="0 1 0" />
                                  <inertial pos="-4.7446E-06 2.3008E-05 0.023958" quat="1.0 0.0 0.0 0.0" mass="0.045" diaginertia="6.4181e-06 5.9794e-06 2.458e-06" />
                                  <geom name="rl_dg_2_3_collision" pos="0 0 0" quat="1.0 0.0 0.0 0.0" type="mesh" mesh="rl_dg_2_3_c.STL" class="collision" />
                                  <body name="rl_dg_2_4" pos="0.0 0.0 0.0388" quat="1.0 0.0 0.0 0.0">
                                    <joint name="rj_dg_2_4" type="hinge" ref="0.0" class="motor" range="-1.5707963267948966 1.5707963267948966" axis="0 1 0" />
                                    <inertial pos="-0.00070816 0.00043036 0.017842" quat="1.0 0.0 0.0 0.0" mass="0.025" diaginertia="2.8592e-06 2.3907e-06 1.6592e-06" />
                                    <geom name="rl_dg_2_4_collision" pos="0 0 0" quat="1.0 0.0 0.0 0.0" type="mesh" mesh="rl_dg_2_4_c.STL" class="collision" />
                                    <body name="rl_dg_2_tip" pos="0.0 0.0 0.0255" quat="1.0 0.0 0.0 0.0">
                                      <body name="right_index_tip_site" pos="0 0 0" quat="1 0 0 0">
                                        <site name="right_index_tip_site" group="2" size="0.002 0.002 0.002"/>
                                      </body>
                                      <inertial pos="0.0038062910498208 5.47903831610297E-07 0.00715699051285251" quat="1.0 0.0 0.0 0.0" mass="0.005" diaginertia="3.24447323464583e-07 1.98954959099231e-07 2.56982145081954e-07" />
                                      <geom name="rl_dg_2_tip_collision" pos="0 0 0" quat="1.0 0.0 0.0 0.0" type="mesh" mesh="rl_dg_2_tip_c.STL" class="collision" />
                                    </body>
                                  </body>
                                </body>
                              </body>
                            </body>
                            <body name="rl_dg_3_1" pos="-0.0071 0.0025 0.0701" quat="1.0 0.0 0.0 0.0">
                              <joint name="rj_dg_3_1" type="hinge" ref="0.0" class="motor" range="-0.6108652381980153 0.6108652381980153" axis="1 0 0" />
                              <inertial pos="0.0012558 -0.00017703 0.023374" quat="1.0 0.0 0.0 0.0" mass="0.045" diaginertia="6.233e-06 9.3331e-06 6.7817e-06" />
                              <geom name="rl_dg_3_1_collision" pos="0 0 0" quat="1.0 0.0 0.0 0.0" type="mesh" mesh="rl_dg_3_1_c.STL" class="collision" />
                              <body name="rl_dg_3_2" pos="0.01765 0.0 0.0265" quat="1.0 0.0 0.0 0.0">
                                <joint name="rj_dg_3_2" type="hinge" ref="0.0" class="motor" range="0.0 1.9547687622336491" axis="0 1 0" />
                                <inertial pos="-4.7446E-06 2.3008E-05 0.023958" quat="1.0 0.0 0.0 0.0" mass="0.045" diaginertia="6.4181e-06 5.9794e-06 2.458e-06" />
                                <geom name="rl_dg_3_2_collision" pos="0 0 0" quat="1.0 0.0 0.0 0.0" type="mesh" mesh="rl_dg_3_2_c.STL" class="collision" />
                                <body name="rl_dg_3_3" pos="0.0 0.0 0.0388" quat="1.0 0.0 0.0 0.0">
                                  <joint name="rj_dg_3_3" type="hinge" ref="0.0" class="motor" range="-1.5707963267948966 1.5707963267948966" axis="0 1 0" />
                                  <inertial pos="-4.7446E-06 2.3008E-05 0.023958" quat="1.0 0.0 0.0 0.0" mass="0.045" diaginertia="6.4181e-06 5.9794e-06 2.458e-06" />
                                  <geom name="rl_dg_3_3_collision" pos="0 0 0" quat="1.0 0.0 0.0 0.0" type="mesh" mesh="rl_dg_3_3_c.STL" class="collision" />
                                  <body name="rl_dg_3_4" pos="0.0 0.0 0.0388" quat="1.0 0.0 0.0 0.0">
                                    <joint name="rj_dg_3_4" type="hinge" ref="0.0" class="motor" range="-1.5707963267948966 1.5707963267948966" axis="0 1 0" />
                                    <inertial pos="-0.00070816 0.00043036 0.017842" quat="1.0 0.0 0.0 0.0" mass="0.025" diaginertia="2.8592e-06 2.3907e-06 1.6592e-06" />
                                    <geom name="rl_dg_3_4_collision" pos="0 0 0" quat="1.0 0.0 0.0 0.0" type="mesh" mesh="rl_dg_3_4_c.STL" class="collision" />
                                    <body name="rl_dg_3_tip" pos="0.0 0.0 0.0255" quat="1.0 0.0 0.0 0.0">
                                      <body name="right_middle_tip_site" pos="0 0 0" quat="1 0 0 0">
                                        <site name="right_middle_tip_site" group="2" size="0.002 0.002 0.002"/>
                                      </body>
                                      <inertial pos="0.0038062910498208 5.47903831610297E-07 0.00715699051285251" quat="1.0 0.0 0.0 0.0" mass="0.005" diaginertia="3.24447323464583e-07 1.98954959099231e-07 2.56982145081954e-07" />
                                      <geom name="rl_dg_3_tip_collision" pos="0 0 0" quat="1.0 0.0 0.0 0.0" type="mesh" mesh="rl_dg_3_tip_c.STL" class="collision" />
                                    </body>
                                  </body>
                                </body>
                              </body>
                            </body>
                            <body name="rl_dg_4_1" pos="-0.0071 -0.022 0.0621" quat="1.0 0.0 0.0 0.0">
                              <joint name="rj_dg_4_1" type="hinge" ref="0.0" class="motor" range="-0.6108652381980153 0.4188790204786391" axis="1 0 0" />
                              <inertial pos="6.0566E-05 -0.00058566 0.023499" quat="1.0 0.0 0.0 0.0" mass="0.045" diaginertia="6.5541e-06 9.5306e-06 7.0879e-06" />
                              <geom name="rl_dg_4_1_collision" pos="0 0 0" quat="1.0 0.0 0.0 0.0" type="mesh" mesh="rl_dg_4_1_c.STL" class="collision" />
                              <body name="rl_dg_4_2" pos="0.01765 0.0 0.0265" quat="1.0 0.0 0.0 0.0">
                                <joint name="rj_dg_4_2" type="hinge" ref="0.0" class="motor" range="0.0 1.9024088846738192" axis="0 1 0" />
                                <inertial pos="-4.7446E-06 2.3008E-05 0.023958" quat="1.0 0.0 0.0 0.0" mass="0.045" diaginertia="6.4181e-06 5.9794e-06 2.458e-06" />
                                <geom name="rl_dg_4_2_collision" pos="0 0 0" quat="1.0 0.0 0.0 0.0" type="mesh" mesh="rl_dg_4_2_c.STL" class="collision" />
                                <body name="rl_dg_4_3" pos="0.0 0.0 0.0388" quat="1.0 0.0 0.0 0.0">
                                  <joint name="rj_dg_4_3" type="hinge" ref="0.0" class="motor" range="-1.5707963267948966 1.5707963267948966" axis="0 1 0" />
                                  <inertial pos="-4.7446E-06 2.3008E-05 0.023958" quat="1.0 0.0 0.0 0.0" mass="0.045" diaginertia="6.4181e-06 5.9794e-06 2.458e-06" />
                                  <geom name="rl_dg_4_3_collision" pos="0 0 0" quat="1.0 0.0 0.0 0.0" type="mesh" mesh="rl_dg_4_3_c.STL" class="collision" />
                                  <body name="rl_dg_4_4" pos="0.0 0.0 0.0388" quat="1.0 0.0 0.0 0.0">
                                    <joint name="rj_dg_4_4" type="hinge" ref="0.0" class="motor" range="-1.5707963267948966 1.5707963267948966" axis="0 1 0" />
                                    <inertial pos="-0.00070816 0.00043036 0.017842" quat="1.0 0.0 0.0 0.0" mass="0.025" diaginertia="2.8592e-06 2.3907e-06 1.6592e-06" />
                                    <geom name="rl_dg_4_4_collision" pos="0 0 0" quat="1.0 0.0 0.0 0.0" type="mesh" mesh="rl_dg_4_4_c.STL" class="collision" />
                                    <body name="rl_dg_4_tip" pos="0.0 0.0 0.0255" quat="1.0 0.0 0.0 0.0">
                                      <body name="right_ring_tip_site" pos="0 0 0" quat="1 0 0 0">
                                        <site name="right_ring_tip_site" group="2" size="0.002 0.002 0.002"/>
                                      </body>
                                      <inertial pos="0.0038062910498208 5.47903831610297E-07 0.00715699051285251" quat="1.0 0.0 0.0 0.0" mass="0.005" diaginertia="3.24447323464583e-07 1.98954959099231e-07 2.56982145081954e-07" />
                                      <geom name="rl_dg_4_tip_collision" pos="0 0 0" quat="1.0 0.0 0.0 0.0" type="mesh" mesh="rl_dg_4_tip_c.STL" class="collision" />
                                    </body>
                                  </body>
                                </body>
                              </body>
                            </body>
                            <body name="rl_dg_5_1" pos="0.0103 -0.0195 0.0182" quat="1.0 0.0 0.0 0.0">
                              <joint name="rj_dg_5_1" type="hinge" ref="0.0" class="motor" range="-0.017453292519943295 1.0471975511965976" axis="0 0 1" />
                              <inertial pos="-0.00433013582483537 -0.0250157327042134 0.0140244480786593" quat="1.0 0.0 0.0 0.0" mass="0.055" diaginertia="2.36207639664085e-05 2.36540063110524e-05 1.12977296557035e-05" />
                              <geom name="rl_dg_5_1_collision" pos="0 0 0" quat="1.0 0.0 0.0 0.0" type="mesh" mesh="rl_dg_5_1_c.STL" class="collision" />
                              <body name="rl_dg_5_2" pos="0.0 -0.028 0.0381" quat="1.0 0.0 0.0 0.0">
                                <joint name="rj_dg_5_2" type="hinge" ref="0.0" class="motor" range="-0.4188790204786391 0.6108652381980153" axis="1 0 0" />
                                <inertial pos="-0.000537630631570108 0.000537630708726741 0.0155000698139622" quat="1.0 0.0 0.0 0.0" mass="0.025" diaginertia="1.99384439440442e-06 1.99384475671682e-06 1.4598228332417e-06" />
                                <geom name="rl_dg_5_2_collision" pos="0 0 0" quat="1.0 0.0 0.0 0.0" type="mesh" mesh="rl_dg_5_2_c.STL" class="collision" />
                                <body name="rl_dg_5_3" pos="0.0 0.0 0.031" quat="1.0 0.0 0.0 0.0">
                                  <joint name="rj_dg_5_3" type="hinge" ref="0.0" class="motor" range="-1.5707963267948966 1.5707963267948966" axis="0 1 0" />
                                  <inertial pos="4.7446492172469E-06 2.30083649378834E-05 0.0148418615456518" quat="1.0 0.0 0.0 0.0" mass="0.045" diaginertia="6.41805423935041e-06 5.97938336588576e-06 2.4580051713906e-06" />
                                  <geom name="rl_dg_5_3_collision" pos="0 0 0" quat="1.0 0.0 0.0 0.0" type="mesh" mesh="rl_dg_5_3_c.STL" class="collision" />
                                  <body name="rl_dg_5_4" pos="0.0 0.0 0.0388" quat="1.0 0.0 0.0 0.0">
                                    <joint name="rj_dg_5_4" type="hinge" ref="0.0" class="motor" range="-1.5707963267948966 1.5707963267948966" axis="0 1 0" />
                                    <inertial pos="-0.000365388872256418 -0.000204821110631699 0.0187946706549663" quat="1.0 0.0 0.0 0.0" mass="0.045" diaginertia="9.81936385229629e-06 9.49149264777591e-06 2.93905089746507e-06" />
                                    <geom name="rl_dg_5_4_collision" pos="0 0 0" quat="1.0 0.0 0.0 0.0" type="mesh" mesh="rl_dg_5_4_c.STL" class="collision" />
                                    <body name="rl_dg_5_tip" pos="0.0 0.0 0.0363" quat="1.0 0.0 0.0 0.0">
                                      <body name="right_pinky_tip_site" pos="0 0 0" quat="1 0 0 0">
                                        <site name="right_pinky_tip_site" group="2" size="0.002 0.002 0.002"/>
                                      </body>
                                      <inertial pos="0.0038062910498208 5.47903831610297E-07 0.00715699051285251" quat="1.0 0.0 0.0 0.0" mass="0.005" diaginertia="3.24447323464583e-07 1.98954959099231e-07 2.56982145081954e-07" />
                                      <geom name="rl_dg_5_tip_collision" pos="0 0 0" quat="1.0 0.0 0.0 0.0" type="mesh" mesh="rl_dg_5_tip_c.STL" class="collision" />
                                    </body>
                                  </body>
                                </body>
                              </body>
                            </body>
                          </body>
                        </body>
                      </body>
                    </body>
                  </body>
                </body>
              </body>
            </body>
          </body>
        </body>
      </body>
    </body>
    <!-- START MOCAP -->
    <body mocap="true" name="right-wrist" pos="0.47000000000000003 -0.29999999999999993 0.8999999999999999" quat="0 0.7071 0.7071 0">
      <site pos="0 0 0" name="right-wrist-site-mocap" rgba="1 0 0 1" size="0.005 0.005 0.005" group="2"/>
    </body>
    <body mocap="true" name="right-thumb-tip" pos="0.56 -0.42999999999999994 0.9169999999999999" quat="0.2706 0.6533 0.2706 -0.6533">
      <site pos="0 0 0" name="right-thumb-tip-site-mocap" rgba="1 0 0 1" size="0.005 0.005 0.005" group="2"/>
    </body>
    <body mocap="true" name="right-index-finger-tip" pos="0.65 -0.32999999999999996 0.8999999999999999" quat="0 0.7071 0.7071 0">
      <site pos="0 0 0" name="right-index-finger-tip-site-mocap" rgba="1 0 0 1" size="0.005 0.005 0.005" group="2"/>
    </body>
    <body mocap="true" name="right-middle-finger-tip" pos="0.655 -0.30999999999999994 0.8999999999999999" quat="0 0.7071 0.7071 0">
      <site pos="0 0 0" name="right-middle-finger-tip-site-mocap" rgba="1 0 0 1" size="0.005 0.005 0.005" group="2"/>
    </body>
    <body mocap="true" name="right-ring-finger-tip" pos="0.649 -0.2899999999999999 0.8999999999999999" quat="0 0.7071 0.7071 0">
      <site pos="0 0 0" name="right-ring-finger-tip-site-mocap" rgba="1 0 0 1" size="0.005 0.005 0.005" group="2"/>
    </body>
    <body mocap="true" name="right-pinky-finger-tip" pos="0.643 -0.2699999999999999 0.8999999999999999" quat="0 0.7071 0.7071 0">
      <site pos="0 0 0" name="right-pinky-finger-tip-site-mocap" rgba="1 0 0 1" size="0.005 0.005 0.005" group="2"/>
    </body>
    <body mocap="true" name="left-wrist" pos="-0.33 -0.29999999999999993 0.8999999999999999" quat="0 0.7071 0.7071 0">
      <site pos="0 0 0" name="left-wrist-site-mocap" rgba="1 0 0 1" size="0.005 0.005 0.005" group="2"/>
    </body>
    <body mocap="true" name="left-thumb-tip" pos="-0.24000000000000005 -0.16999999999999993 0.9169999999999999" quat="0.6533 -0.2706 -0.6533 -0.2706">
      <site pos="0 0 0" name="left-thumb-tip-site-mocap" rgba="1 0 0 1" size="0.005 0.005 0.005" group="2"/>
    </body>
    <body mocap="true" name="left-index-finger-tip" pos="-0.15000000000000002 -0.2699999999999999 0.8999999999999999" quat="0 0.7071 0.7071 0">
      <site pos="0 0 0" name="left-index-finger-tip-site-mocap" rgba="1 0 0 1" size="0.005 0.005 0.005" group="2"/>
    </body>
    <body mocap="true" name="left-middle-finger-tip" pos="-0.14500000000000005 -0.2899999999999999 0.8999999999999999" quat="0 0.7071 0.7071 0">
      <site pos="0 0 0" name="left-middle-finger-tip-site-mocap" rgba="1 0 0 1" size="0.005 0.005 0.005" group="2"/>
    </body>
    <body mocap="true" name="left-ring-finger-tip" pos="-0.15100000000000002 -0.30999999999999994 0.8999999999999999" quat="0 0.7071 0.7071 0">
      <site pos="0 0 0" name="left-ring-finger-tip-site-mocap" rgba="1 0 0 1" size="0.005 0.005 0.005" group="2"/>
    </body>
    <body mocap="true" name="left-pinky-finger-tip" pos="-0.15700000000000003 -0.32999999999999996 0.8999999999999999" quat="0 0.7071 0.7071 0">
      <site pos="0 0 0" name="left-pinky-finger-tip-site-mocap" rgba="1 0 0 1" size="0.005 0.005 0.005" group="2"/>
    </body>
    <light name="key" pos="1.45 -0.19999999999999996 1.1" dir="-1 -0.5 -0.5" cutoff="45" diffuse="0.3 0.3 0.3" directional="true"/>
    <light name="fill" pos="1.25 -1.4 1.0" dir="-0.8 0.5 -0.6" cutoff="60" diffuse="0.18 0.18 0.18" directional="true"/>
    <light name="back" pos="-0.35000000000000003 -0.7 1.7999999999999998" dir="-1 0 1" cutoff="50" diffuse="0.5 0.5 0.5" directional="true"/>
    <body name="concrete-slab" pos="0 0 0.6">
    <geom name="concrete-slab-concrete" type="box" group="1" material="concrete-slab-concrete" size="0.7 0.7 0.05" pos="0 0 -"/>
    </body>
    <body name="box" pos="0.6 0 0.9">
      <inertial pos="0 0 0" mass="0.1" diaginertia="0.001 0.001 0.001" />
      <geom name="box" type="box" size="0.05 0.05 0.05" material="box" contype="1" conaffinity="1" />
      <joint name="box_joint" type="free" damping="0.01" />
    </body>
    <camera name="left" pos="0.0 0.9000000000000001 1.075" fovy="42.5" xyaxes="-1.0 0.0 0.0 0.0 -0.20039623614870655 0.9797149322825656"/>
    <camera name="right" pos="0.0 -1.3 1.075" fovy="42.5" xyaxes="1.0 0.0 0.0 -0.0 0.20039623614870655 0.9797149322825656"/>
    <!-- END MOCAP -->
  </worldbody>
  
  <equality>
    <weld site1="right-wrist-site-mocap" site2="right_palm_site"/>
    <weld site1="right-thumb-tip-site-mocap" site2="right_thumb_tip_site"/>
    <weld site1="right-index-finger-tip-site-mocap" site2="right_index_tip_site"/>
    <weld site1="right-middle-finger-tip-site-mocap" site2="right_middle_tip_site"/>
    <weld site1="right-ring-finger-tip-site-mocap" site2="right_ring_tip_site"/>
    <weld site1="right-pinky-finger-tip-site-mocap" site2="right_pinky_tip_site"/>
    <weld site1="left-wrist-site-mocap" site2="left_palm_site"/>
    <weld site1="left-thumb-tip-site-mocap" site2="left_thumb_tip_site"/>
    <weld site1="left-index-finger-tip-site-mocap" site2="left_index_tip_site"/>
    <weld site1="left-middle-finger-tip-site-mocap" site2="left_middle_tip_site"/>
    <weld site1="left-ring-finger-tip-site-mocap" site2="left_ring_tip_site"/>
    <weld site1="left-pinky-finger-tip-site-mocap" site2="left_pinky_tip_site"/>
  </equality>

  <actuator>
    <position name="panda_left_joint1_ctrl" joint="panda_left_joint1" class="motor" />
    <position name="panda_left_joint2_ctrl" joint="panda_left_joint2" class="motor" />
    <position name="panda_left_joint3_ctrl" joint="panda_left_joint3" class="motor" />
    <position name="panda_left_joint4_ctrl" joint="panda_left_joint4" class="motor" />
    <position name="panda_left_joint5_ctrl" joint="panda_left_joint5" class="motor" />
    <position name="panda_left_joint6_ctrl" joint="panda_left_joint6" class="motor" />
    <position name="panda_left_joint7_ctrl" joint="panda_left_joint7" class="motor" />
    <position name="lj_dg_1_1_ctrl" joint="lj_dg_1_1" class="motor" />
    <position name="lj_dg_1_2_ctrl" joint="lj_dg_1_2" class="motor" />
    <position name="lj_dg_1_3_ctrl" joint="lj_dg_1_3" class="motor" />
    <position name="lj_dg_1_4_ctrl" joint="lj_dg_1_4" class="motor" />
    <position name="lj_dg_2_1_ctrl" joint="lj_dg_2_1" class="motor" />
    <position name="lj_dg_2_2_ctrl" joint="lj_dg_2_2" class="motor" />
    <position name="lj_dg_2_3_ctrl" joint="lj_dg_2_3" class="motor" />
    <position name="lj_dg_2_4_ctrl" joint="lj_dg_2_4" class="motor" />
    <position name="lj_dg_3_1_ctrl" joint="lj_dg_3_1" class="motor" />
    <position name="lj_dg_3_2_ctrl" joint="lj_dg_3_2" class="motor" />
    <position name="lj_dg_3_3_ctrl" joint="lj_dg_3_3" class="motor" />
    <position name="lj_dg_3_4_ctrl" joint="lj_dg_3_4" class="motor" />
    <position name="lj_dg_4_1_ctrl" joint="lj_dg_4_1" class="motor" />
    <position name="lj_dg_4_2_ctrl" joint="lj_dg_4_2" class="motor" />
    <position name="lj_dg_4_3_ctrl" joint="lj_dg_4_3" class="motor" />
    <position name="lj_dg_4_4_ctrl" joint="lj_dg_4_4" class="motor" />
    <position name="lj_dg_5_1_ctrl" joint="lj_dg_5_1" class="motor" />
    <position name="lj_dg_5_2_ctrl" joint="lj_dg_5_2" class="motor" />
    <position name="lj_dg_5_3_ctrl" joint="lj_dg_5_3" class="motor" />
    <position name="lj_dg_5_4_ctrl" joint="lj_dg_5_4" class="motor" />
    <position name="panda_right_joint1_ctrl" joint="panda_right_joint1" class="motor" />
    <position name="panda_right_joint2_ctrl" joint="panda_right_joint2" class="motor" />
    <position name="panda_right_joint3_ctrl" joint="panda_right_joint3" class="motor" />
    <position name="panda_right_joint4_ctrl" joint="panda_right_joint4" class="motor" />
    <position name="panda_right_joint5_ctrl" joint="panda_right_joint5" class="motor" />
    <position name="panda_right_joint6_ctrl" joint="panda_right_joint6" class="motor" />
    <position name="panda_right_joint7_ctrl" joint="panda_right_joint7" class="motor" />
    <position name="rj_dg_1_1_ctrl" joint="rj_dg_1_1" class="motor" />
    <position name="rj_dg_1_2_ctrl" joint="rj_dg_1_2" class="motor" />
    <position name="rj_dg_1_3_ctrl" joint="rj_dg_1_3" class="motor" />
    <position name="rj_dg_1_4_ctrl" joint="rj_dg_1_4" class="motor" />
    <position name="rj_dg_2_1_ctrl" joint="rj_dg_2_1" class="motor" />
    <position name="rj_dg_2_2_ctrl" joint="rj_dg_2_2" class="motor" />
    <position name="rj_dg_2_3_ctrl" joint="rj_dg_2_3" class="motor" />
    <position name="rj_dg_2_4_ctrl" joint="rj_dg_2_4" class="motor" />
    <position name="rj_dg_3_1_ctrl" joint="rj_dg_3_1" class="motor" />
    <position name="rj_dg_3_2_ctrl" joint="rj_dg_3_2" class="motor" />
    <position name="rj_dg_3_3_ctrl" joint="rj_dg_3_3" class="motor" />
    <position name="rj_dg_3_4_ctrl" joint="rj_dg_3_4" class="motor" />
    <position name="rj_dg_4_1_ctrl" joint="rj_dg_4_1" class="motor" />
    <position name="rj_dg_4_2_ctrl" joint="rj_dg_4_2" class="motor" />
    <position name="rj_dg_4_3_ctrl" joint="rj_dg_4_3" class="motor" />
    <position name="rj_dg_4_4_ctrl" joint="rj_dg_4_4" class="motor" />
    <position name="rj_dg_5_1_ctrl" joint="rj_dg_5_1" class="motor" />
    <position name="rj_dg_5_2_ctrl" joint="rj_dg_5_2" class="motor" />
    <position name="rj_dg_5_3_ctrl" joint="rj_dg_5_3" class="motor" />
    <position name="rj_dg_5_4_ctrl" joint="rj_dg_5_4" class="motor" />
  </actuator>

  <contact>
    <exclude body1="panda_left_link0" body2="panda_left_link1" />
    <exclude body1="panda_left_link1" body2="panda_left_link2" />
    <exclude body1="panda_left_link2" body2="panda_left_link3" />
    <exclude body1="panda_left_link3" body2="panda_left_link4" />
    <exclude body1="panda_left_link4" body2="panda_left_link5" />
    <exclude body1="panda_left_link5" body2="panda_left_link6" />
    <exclude body1="panda_left_link6" body2="panda_left_link7" />
    <exclude body1="ll_dg_mount" body2="ll_dg_base" />
    <exclude body1="ll_dg_base" body2="ll_dg_palm" />
    <exclude body1="ll_dg_palm" body2="ll_dg_1_1" />
    <exclude body1="ll_dg_1_1" body2="ll_dg_1_2" />
    <exclude body1="ll_dg_1_2" body2="ll_dg_1_3" />
    <exclude body1="ll_dg_1_3" body2="ll_dg_1_4" />
    <exclude body1="ll_dg_1_4" body2="ll_dg_1_tip" />
    <exclude body1="ll_dg_palm" body2="ll_dg_2_1" />
    <exclude body1="ll_dg_2_1" body2="ll_dg_2_2" />
    <exclude body1="ll_dg_2_2" body2="ll_dg_2_3" />
    <exclude body1="ll_dg_2_3" body2="ll_dg_2_4" />
    <exclude body1="ll_dg_2_4" body2="ll_dg_2_tip" />
    <exclude body1="ll_dg_palm" body2="ll_dg_3_1" />
    <exclude body1="ll_dg_3_1" body2="ll_dg_3_2" />
    <exclude body1="ll_dg_3_2" body2="ll_dg_3_3" />
    <exclude body1="ll_dg_3_3" body2="ll_dg_3_4" />
    <exclude body1="ll_dg_3_4" body2="ll_dg_3_tip" />
    <exclude body1="ll_dg_palm" body2="ll_dg_4_1" />
    <exclude body1="ll_dg_4_1" body2="ll_dg_4_2" />
    <exclude body1="ll_dg_4_2" body2="ll_dg_4_3" />
    <exclude body1="ll_dg_4_3" body2="ll_dg_4_4" />
    <exclude body1="ll_dg_4_4" body2="ll_dg_4_tip" />
    <exclude body1="ll_dg_palm" body2="ll_dg_5_1" />
    <exclude body1="ll_dg_5_1" body2="ll_dg_5_2" />
    <exclude body1="ll_dg_5_2" body2="ll_dg_5_3" />
    <exclude body1="ll_dg_5_3" body2="ll_dg_5_4" />
    <exclude body1="ll_dg_5_4" body2="ll_dg_5_tip" />
    <exclude body1="panda_right_link0" body2="panda_right_link1" />
    <exclude body1="panda_right_link1" body2="panda_right_link2" />
    <exclude body1="panda_right_link2" body2="panda_right_link3" />
    <exclude body1="panda_right_link3" body2="panda_right_link4" />
    <exclude body1="panda_right_link4" body2="panda_right_link5" />
    <exclude body1="panda_right_link5" body2="panda_right_link6" />
    <exclude body1="panda_right_link6" body2="panda_right_link7" />
    <exclude body1="rl_dg_mount" body2="rl_dg_base" />
    <exclude body1="rl_dg_base" body2="rl_dg_palm" />
    <exclude body1="rl_dg_palm" body2="rl_dg_1_1" />
    <exclude body1="rl_dg_1_1" body2="rl_dg_1_2" />
    <exclude body1="rl_dg_1_2" body2="rl_dg_1_3" />
    <exclude body1="rl_dg_1_3" body2="rl_dg_1_4" />
    <exclude body1="rl_dg_1_4" body2="rl_dg_1_tip" />
    <exclude body1="rl_dg_palm" body2="rl_dg_2_1" />
    <exclude body1="rl_dg_2_1" body2="rl_dg_2_2" />
    <exclude body1="rl_dg_2_2" body2="rl_dg_2_3" />
    <exclude body1="rl_dg_2_3" body2="rl_dg_2_4" />
    <exclude body1="rl_dg_2_4" body2="rl_dg_2_tip" />
    <exclude body1="rl_dg_palm" body2="rl_dg_3_1" />
    <exclude body1="rl_dg_3_1" body2="rl_dg_3_2" />
    <exclude body1="rl_dg_3_2" body2="rl_dg_3_3" />
    <exclude body1="rl_dg_3_3" body2="rl_dg_3_4" />
    <exclude body1="rl_dg_3_4" body2="rl_dg_3_tip" />
    <exclude body1="rl_dg_palm" body2="rl_dg_4_1" />
    <exclude body1="rl_dg_4_1" body2="rl_dg_4_2" />
    <exclude body1="rl_dg_4_2" body2="rl_dg_4_3" />
    <exclude body1="rl_dg_4_3" body2="rl_dg_4_4" />
    <exclude body1="rl_dg_4_4" body2="rl_dg_4_tip" />
    <exclude body1="rl_dg_palm" body2="rl_dg_5_1" />
    <exclude body1="rl_dg_5_1" body2="rl_dg_5_2" />
    <exclude body1="rl_dg_5_2" body2="rl_dg_5_3" />
    <exclude body1="rl_dg_5_3" body2="rl_dg_5_4" />
    <exclude body1="rl_dg_5_4" body2="rl_dg_5_tip" />
  </contact>
  
  <keyframe>
      <key name="home" qpos="0.12851247 -0.74926734 0.01523919 -2.5314567 1.3384545 1.8232623 0.72626555 -0.4 0.07 -0.81 0.23 0.14 0.44 0.31 -0.29 0.08 0.52 0.51 -1.03 0.1 0.77 -0.33 -0.56 -0.43 0.03 -0.12 1.21 -0.30540678 -0.79184073 0.06812683 -2.5840569 -1.3527942 2.0385659 0.62929636 0.3 -0.04 0.6 -0.02 -0.08 0.23 0.25 -0.22 -0.07 0.08 0.69 -0.82 -0.04 0.28 -0.02 -0.17 0. 0. 0.71 -1.33" />
  </keyframe>

</mujoco>
