<?xml version='1.0' encoding='utf-8'?>
<mujoco model="robot_scene">
  <compiler angle="radian" coordinate="local" meshdir="." strippath="false" />
  <option>
    <flag filterparent="disable" />
  </option>
  <asset>
    <texture name="grid" type="2d" builtin="checker" rgb1="0.1 0.2 0.3" rgb2="0.2 0.3 0.4" width="300" height="300" />
    <material name="grid" texture="grid" texrepeat="1 1" />
    <material name="table" rgba="0.8 0.8 0.8 1" />
    <material name="box" rgba="0.9 0.3 0.3 1" />
    <material name="black_box" rgba="0.05 0.05 0.05 1" />
    <texture name="skybox" type="skybox" builtin="gradient" rgb1="0.3 0.5 0.7" rgb2="0.1 0.2 0.3" width="512" height="512" />
    <mesh name="mesh_panda_left_link0" file="collision_simplified/panda_left_link0/link0.stl" />
    <mesh name="mesh_panda_left_link1" file="collision_simplified/panda_left_link1/link1.stl" />
    <mesh name="mesh_panda_left_link2" file="collision_simplified/panda_left_link2/link2.stl" />
    <mesh name="mesh_panda_left_link3" file="collision_simplified/panda_left_link3/link3.stl" />
    <mesh name="mesh_panda_left_link4" file="collision_simplified/panda_left_link4/link4.stl" />
    <mesh name="mesh_panda_left_link5" file="collision_simplified/panda_left_link5/link5.stl" />
    <mesh name="mesh_panda_left_link6" file="collision_simplified/panda_left_link6/link6.stl" />
    <mesh name="mesh_panda_left_link7" file="collision_simplified/panda_left_link7/link7.stl" />
    <mesh name="mesh_ll_dg_base" file="collision_simplified/ll_dg_base/ll_dg_base_c.STL" />
    <mesh name="mesh_ll_dg_palm" file="collision_simplified/ll_dg_palm/ll_dg_palm_c.STL" />
    <mesh name="mesh_ll_dg_1_3" file="collision_simplified/ll_dg_1_3/ll_dg_1_3_c.STL" />
    <mesh name="mesh_ll_dg_1_4" file="collision_simplified/ll_dg_1_4/ll_dg_1_4_c.STL" />
    <mesh name="mesh_ll_dg_1_tip" file="collision_simplified/ll_dg_1_tip/ll_dg_1_tip_c.STL" />
    <mesh name="mesh_ll_dg_2_1" file="collision_simplified/ll_dg_2_1/ll_dg_2_1_c.STL" />
    <mesh name="mesh_ll_dg_2_2" file="collision_simplified/ll_dg_2_2/ll_dg_2_2_c.STL" />
    <mesh name="mesh_ll_dg_2_3" file="collision_simplified/ll_dg_2_3/ll_dg_2_3_c.STL" />
    <mesh name="mesh_ll_dg_2_4" file="collision_simplified/ll_dg_2_4/ll_dg_2_4_c.STL" />
    <mesh name="mesh_ll_dg_2_tip" file="collision_simplified/ll_dg_2_tip/ll_dg_2_tip_c.STL" />
    <mesh name="mesh_ll_dg_3_1" file="collision_simplified/ll_dg_3_1/ll_dg_3_1_c.STL" />
    <mesh name="mesh_ll_dg_3_2" file="collision_simplified/ll_dg_3_2/ll_dg_3_2_c.STL" />
    <mesh name="mesh_ll_dg_3_3" file="collision_simplified/ll_dg_3_3/ll_dg_3_3_c.STL" />
    <mesh name="mesh_ll_dg_3_4" file="collision_simplified/ll_dg_3_4/ll_dg_3_4_c.STL" />
    <mesh name="mesh_ll_dg_3_tip" file="collision_simplified/ll_dg_3_tip/ll_dg_3_tip_c.STL" />
    <mesh name="mesh_ll_dg_4_1" file="collision_simplified/ll_dg_4_1/ll_dg_4_1_c.STL" />
    <mesh name="mesh_ll_dg_4_2" file="collision_simplified/ll_dg_4_2/ll_dg_4_2_c.STL" />
    <mesh name="mesh_ll_dg_4_3" file="collision_simplified/ll_dg_4_3/ll_dg_4_3_c.STL" />
    <mesh name="mesh_ll_dg_4_4" file="collision_simplified/ll_dg_4_4/ll_dg_4_4_c.STL" />
    <mesh name="mesh_ll_dg_4_tip" file="collision_simplified/ll_dg_4_tip/ll_dg_4_tip_c.STL" />
    <mesh name="mesh_ll_dg_5_1" file="collision_simplified/ll_dg_5_1/ll_dg_5_1_c.STL" />
    <mesh name="mesh_ll_dg_5_2" file="collision_simplified/ll_dg_5_2/ll_dg_5_2_c.STL" />
    <mesh name="mesh_ll_dg_5_3" file="collision_simplified/ll_dg_5_3/ll_dg_5_3_c.STL" />
    <mesh name="mesh_ll_dg_5_4" file="collision_simplified/ll_dg_5_4/ll_dg_5_4_c.STL" />
    <mesh name="mesh_ll_dg_5_tip" file="collision_simplified/ll_dg_5_tip/ll_dg_5_tip_c.STL" />
    <mesh name="mesh_panda_link0" file="collision_simplified/panda_link0/link0.stl" />
    <mesh name="mesh_panda_link1" file="collision_simplified/panda_link1/link1.stl" />
    <mesh name="mesh_panda_link2" file="collision_simplified/panda_link2/link2.stl" />
    <mesh name="mesh_panda_link3" file="collision_simplified/panda_link3/link3.stl" />
    <mesh name="mesh_panda_link4" file="collision_simplified/panda_link4/link4.stl" />
    <mesh name="mesh_panda_link5" file="collision_simplified/panda_link5/link5.stl" />
    <mesh name="mesh_panda_link6" file="collision_simplified/panda_link6/link6.stl" />
    <mesh name="mesh_panda_link7" file="collision_simplified/panda_link7/link7.stl" />
    <mesh name="mesh_rl_dg_mount" file="collision_simplified/rl_dg_mount/rl_dg_mount_c.STL" />
    <mesh name="mesh_rl_dg_base" file="collision_simplified/rl_dg_base/rl_dg_base_c.STL" />
    <mesh name="mesh_rl_dg_palm" file="collision_simplified/rl_dg_palm/rl_dg_palm_c.STL" />
    <mesh name="mesh_rl_dg_1_1" file="collision_simplified/rl_dg_1_1/rl_dg_1_1_c.STL" />
    <mesh name="mesh_rl_dg_1_2" file="collision_simplified/rl_dg_1_2/rl_dg_1_2_c.STL" />
    <mesh name="mesh_rl_dg_1_3" file="collision_simplified/rl_dg_1_3/rl_dg_1_3_c.STL" />
    <mesh name="mesh_rl_dg_1_4" file="collision_simplified/rl_dg_1_4/rl_dg_1_4_c.STL" />
    <mesh name="mesh_rl_dg_1_tip" file="collision_simplified/rl_dg_1_tip/rl_dg_1_tip_c.STL" />
    <mesh name="mesh_rl_dg_2_1" file="collision_simplified/rl_dg_2_1/rl_dg_2_1_c.STL" />
    <mesh name="mesh_rl_dg_2_2" file="collision_simplified/rl_dg_2_2/rl_dg_2_2_c.STL" />
    <mesh name="mesh_rl_dg_2_3" file="collision_simplified/rl_dg_2_3/rl_dg_2_3_c.STL" />
    <mesh name="mesh_rl_dg_2_4" file="collision_simplified/rl_dg_2_4/rl_dg_2_4_c.STL" />
    <mesh name="mesh_rl_dg_2_tip" file="collision_simplified/rl_dg_2_tip/rl_dg_2_tip_c.STL" />
    <mesh name="mesh_rl_dg_3_1" file="collision_simplified/rl_dg_3_1/rl_dg_3_1_c.STL" />
    <mesh name="mesh_rl_dg_3_2" file="collision_simplified/rl_dg_3_2/rl_dg_3_2_c.STL" />
    <mesh name="mesh_rl_dg_3_3" file="collision_simplified/rl_dg_3_3/rl_dg_3_3_c.STL" />
    <mesh name="mesh_rl_dg_3_4" file="collision_simplified/rl_dg_3_4/rl_dg_3_4_c.STL" />
    <mesh name="mesh_rl_dg_3_tip" file="collision_simplified/rl_dg_3_tip/rl_dg_3_tip_c.STL" />
    <mesh name="mesh_rl_dg_4_1" file="collision_simplified/rl_dg_4_1/rl_dg_4_1_c.STL" />
    <mesh name="mesh_rl_dg_4_2" file="collision_simplified/rl_dg_4_2/rl_dg_4_2_c.STL" />
    <mesh name="mesh_rl_dg_4_3" file="collision_simplified/rl_dg_4_3/rl_dg_4_3_c.STL" />
    <mesh name="mesh_rl_dg_4_4" file="collision_simplified/rl_dg_4_4/rl_dg_4_4_c.STL" />
    <mesh name="mesh_rl_dg_4_tip" file="collision_simplified/rl_dg_4_tip/rl_dg_4_tip_c.STL" />
    <mesh name="mesh_rl_dg_5_1" file="collision_simplified/rl_dg_5_1/rl_dg_5_1_c.STL" />
    <mesh name="mesh_rl_dg_5_2" file="collision_simplified/rl_dg_5_2/rl_dg_5_2_c.STL" />
    <mesh name="mesh_rl_dg_5_3" file="collision_simplified/rl_dg_5_3/rl_dg_5_3_c.STL" />
    <mesh name="mesh_rl_dg_5_4" file="collision_simplified/rl_dg_5_4/rl_dg_5_4_c.STL" />
    <mesh name="mesh_rl_dg_5_tip" file="collision_simplified/rl_dg_5_tip/rl_dg_5_tip_c.STL" />
  </asset>
  <worldbody>
    <geom name="floor" type="plane" pos="0 0 0" size="10 10 0.1" material="grid" />
    <light pos="0 0 3" dir="0 0 -1" directional="true" />
    <body name="table" pos="0 -0.08 0.9">
      <inertial pos="0 0 0" mass="10" diaginertia="1 1 1" />
      <geom name="table_top" type="box" pos="0 0 0" size="0.8 0.405 0.05" material="table" contype="1" conaffinity="1" />
      <geom type="cylinder" pos="-0.75 -0.355 -0.125" size="0.02 0.075" material="table" contype="1" conaffinity="1" />
      <geom type="cylinder" pos="0.75 -0.355 -0.125" size="0.02 0.075" material="table" contype="1" conaffinity="1" />
      <geom type="cylinder" pos="-0.75 0.355 -0.125" size="0.02 0.075" material="table" contype="1" conaffinity="1" />
      <geom type="cylinder" pos="0.75 0.355 -0.125" size="0.02 0.075" material="table" contype="1" conaffinity="1" />
    </body>
    <body name="black_box" pos="-0.03 -0.17 1.03">
      <inertial pos="0 0 0" mass="0.2" diaginertia="0.01 0.01 0.01" />
      <geom name="black_box" type="box" size="0.345 0.17 0.08" material="black_box" contype="1" conaffinity="1" />
    </body>
    <body name="box" pos="0.0597 -0.3376 1.1835" quat="-0.6413 0.2875 0.6467 -0.2964">
      <inertial pos="0 0 0" mass="0.1" diaginertia="0.001 0.001 0.001" />
      <geom name="box" type="box" size="0.17 0.126 0.0535" material="box" contype="1" conaffinity="1" />
      <joint name="box_joint" type="free" damping="0.01" />
    </body>
    <body name="left_robot_base" pos="0.45 0.4 0.945" quat="0.154 0 0 -0.988">
      <body name="panda_left_link0">
        <inertial pos="-0.041018 -0.00014 0.049974" mass="0.629769" fullinertia="0.00315 0.00388 0.004285 8.2904e-07 0.00015 8.2299e-06" />
        <geom type="mesh" mesh="mesh_panda_left_link0" contype="1" conaffinity="1" />
        <body name="panda_left_link1" pos="0.0 0.0 0.333">
          <inertial pos="0.003875 0.002081 -0.04762" mass="4.970684" fullinertia="0.70337 0.70661 0.009117 -0.000139 0.006772 0.019169" />
          <geom type="mesh" mesh="mesh_panda_left_link1" contype="1" conaffinity="1" />
          <joint name="panda_left_joint1" type="hinge" axis="0.0 0.0 1.0" range="-2.8973 2.8973" />
          <body name="panda_left_link2" euler="-1.5707963267948966 0.0 0.0">
            <inertial pos="-0.003141 -0.02872 0.003495" mass="0.646926" fullinertia="0.007962 0.02811 0.025995 -0.003925 0.010254 0.000704" />
            <geom type="mesh" mesh="mesh_panda_left_link2" contype="1" conaffinity="1" />
            <joint name="panda_left_joint2" type="hinge" axis="0.0 0.0 1.0" range="-1.7628 1.7628" />
            <body name="panda_left_link3" pos="0.0 -0.316 0.0" euler="1.5707963267948966 0.0 0.0">
              <inertial pos="0.027518 0.039252 -0.066502" mass="3.228604" fullinertia="0.037242 0.036155 0.01083 -0.004761 -0.011396 -0.012805" />
              <geom type="mesh" mesh="mesh_panda_left_link3" contype="1" conaffinity="1" />
              <joint name="panda_left_joint3" type="hinge" axis="0.0 0.0 1.0" range="-2.8973 2.8973" />
              <body name="panda_left_link4" pos="0.0825 0.0 0.0" euler="1.5707963267948966 0.0 0.0">
                <inertial pos="-0.05317 0.104419 0.027454" mass="3.587895" fullinertia="0.025853 0.019552 0.028323 0.007796 -0.001332 0.008641" />
                <geom type="mesh" mesh="mesh_panda_left_link4" contype="1" conaffinity="1" />
                <joint name="panda_left_joint4" type="hinge" axis="0.0 0.0 1.0" range="-3.0718 -0.0698" />
                <body name="panda_left_link5" pos="-0.0825 0.384 0.0" euler="-1.5707963267948966 0.0 0.0">
                  <inertial pos="-0.011953 0.041065 -0.038437" mass="1.225946" fullinertia="0.035549 0.029474 0.008627 -0.002117 -0.004037 0.000229" />
                  <geom type="mesh" mesh="mesh_panda_left_link5" contype="1" conaffinity="1" />
                  <joint name="panda_left_joint5" type="hinge" axis="0.0 0.0 1.0" range="-2.8973 2.8973" />
                  <body name="panda_left_link6" euler="1.5707963267948966 0.0 0.0">
                    <inertial pos="0.060149 -0.014117 -0.010517" mass="1.666555" fullinertia="0.001964 0.004354 0.005433 0.000109 -0.001158 0.000341" />
                    <geom type="mesh" mesh="mesh_panda_left_link6" contype="1" conaffinity="1" />
                    <joint name="panda_left_joint6" type="hinge" axis="0.0 0.0 1.0" range="-0.0175 3.7525" />
                    <body name="panda_left_link7" pos="0.088 0.0 0.0" euler="1.5707963267948966 0.0 0.0">
                      <inertial pos="0.010517 -0.004252 0.061597" mass="0.735522" fullinertia="0.012516 0.010027 0.004815 -0.000428 -0.001196 -0.000741" />
                      <geom type="mesh" mesh="mesh_panda_left_link7" contype="1" conaffinity="1" />
                      <joint name="panda_joint7" type="hinge" axis="0.0 0.0 1.0" range="-2.8973 2.8973" />
                      <body name="panda_left_link8">
                        <inertial pos="0 0 0" mass="0.001" diaginertia="1e-06 1e-06 1e-06" />
                        <body name="ll_dg_mount" pos="0.0 0.0 0.1034" euler="0.0 0.0 -0.5">
                          <inertial pos="6.4721e-09 2.1674e-05 0.0049997" mass="0.05" fullinertia="1.0999e-05 1.1018e-05 2.0531e-05 -2.1734e-12 -1.2441e-12 -4.0435e-09" />
                          <body name="ll_dg_base" pos="0.0 0.0 0.004">
                            <inertial pos="-0.00058969 -0.00051381 0.037363" mass="0.45" fullinertia="0.00048608 0.00049085 0.00043369 -1.041e-05 1.7229e-05 5.191e-06" />
                            <geom type="mesh" mesh="mesh_ll_dg_base" contype="1" conaffinity="1" />
                            <body name="ll_dg_palm" pos="0.0 0.0 0.0698">
                              <inertial pos="-0.0089544 -0.00095674 0.041327" mass="0.35" fullinertia="0.00052648 0.00041644 0.00045776 -2.618e-06 -2.2256e-05 4.8923e-05" />
                              <geom type="mesh" mesh="mesh_ll_dg_palm" contype="1" conaffinity="1" />
                              <site name="left_palm_site" pos="0 0 0.02" size="0.002 0.002 0.002" group="2"/>
                              <body name="ll_dg_1_1" pos="-0.0162 -0.019 0.0128">
                                <inertial pos="0.021473 3.1163e-06 0.0028146" mass="0.045" fullinertia="4.2707e-06 1.3718e-05 1.2161e-05 2.4123e-09 2.9055e-06 -1.3824e-09" />
                                <joint name="lj_dg_1_1" type="hinge" axis="1.0 0.0 0.0" range="-0.8901179185171081 0.3839724354387525" />
                                <body name="ll_dg_1_2" pos="0.04195 0.0 0.0">
                                  <inertial pos="-0.00055633 -0.0155 0.00055633" mass="0.025" fullinertia="1.9935e-06 1.459e-06 1.9935e-06 -1.5774e-07 -3.114e-09 -1.5774e-07" />
                                  <joint name="lj_dg_1_2" type="hinge" axis="0.0 0.0 1.0" range="-0.0 3.141592653589793" />
                                  <body name="ll_dg_1_3" pos="0.0 -0.031 0.0">
                                    <inertial pos="-2.3008e-05 -0.014842 4.7446e-06" mass="0.045" fullinertia="5.9794e-06 2.458e-06 6.4181e-06 -3.6014e-07 1.3678e-09 2.3552e-09" />
                                    <geom type="mesh" mesh="mesh_ll_dg_1_3" contype="1" conaffinity="1" />
                                    <joint name="lj_dg_1_3" type="hinge" axis="1.0 0.0 0.0" range="-1.5707963267948966 1.5707963267948966" />
                                    <body name="ll_dg_1_4" pos="0.0 -0.0388 0.0">
                                      <inertial pos="0.00020482 -0.018795 -0.00036539" mass="0.045" fullinertia="9.4915e-06 2.9391e-06 9.8194e-06 -1.5157e-07 -3.4626e-09 -3.7813e-07" />
                                      <geom type="mesh" mesh="mesh_ll_dg_1_4" contype="1" conaffinity="1" />
                                      <joint name="lj_dg_1_4" type="hinge" axis="1.0 0.0 0.0" range="-1.5707963267948966 1.5707963267948966" />
                                      <body name="ll_dg_1_tip" pos="0.0 -0.0363 0.0">
                                        <inertial pos="-5.479e-07 -0.007157 0.0038063" mass="0.005" fullinertia="1e-06 1e-06 1e-06 -3.0731e-11 -2.1191e-12 -1.3375e-08" />
                                        <geom type="mesh" mesh="mesh_ll_dg_1_tip" contype="1" conaffinity="1" />
                                        <site name="left_thumb_tip_site" pos="0 0 0" size="0.002 0.002 0.002" group="2"/>
                                      </body>
                                    </body>
                                  </body>
                                </body>
                              </body>
                              <body name="ll_dg_2_1" pos="-0.0071 -0.027 0.0661">
                                <inertial pos="0.0010606 -0.00058566 0.023499" mass="0.045" fullinertia="6.5541e-06 9.5306e-06 7.0879e-06 1.8684e-07 -1.1508e-06 -5.3298e-09" />
                                <geom type="mesh" mesh="mesh_ll_dg_2_1" contype="1" conaffinity="1" />
                                <joint name="lj_dg_2_1" type="hinge" axis="1.0 0.0 0.0" range="-0.6108652381980153 0.4188790204786391" />
                                <body name="ll_dg_2_2" pos="0.01765 0.0 0.0265">
                                  <inertial pos="-4.7446e-06 2.3008e-05 0.023958" mass="0.045" fullinertia="6.4181e-06 5.9794e-06 2.458e-06 1.3678e-09 -2.3552e-09 3.6014e-07" />
                                  <geom type="mesh" mesh="mesh_ll_dg_2_2" contype="1" conaffinity="1" />
                                  <joint name="lj_dg_2_2" type="hinge" axis="0.0 1.0 0.0" range="-0.0 2.007128639793479" />
                                  <body name="ll_dg_2_3" pos="0.0 0.0 0.0388">
                                    <inertial pos="-4.7446e-06 2.3008e-05 0.023958" mass="0.045" fullinertia="6.4181e-06 5.9794e-06 2.458e-06 1.3678e-09 -2.3552e-09 3.6014e-07" />
                                    <geom type="mesh" mesh="mesh_ll_dg_2_3" contype="1" conaffinity="1" />
                                    <joint name="lj_dg_2_3" type="hinge" axis="0.0 1.0 0.0" range="-1.5707963267948966 1.5707963267948966" />
                                    <body name="ll_dg_2_4" pos="0.0 0.0 0.0388">
                                      <inertial pos="-0.00070816 0.00043036 0.017842" mass="0.025" fullinertia="2.8592e-06 2.3907e-06 1.6592e-06 -5.9306e-09 2.1028e-07 1.8286e-07" />
                                      <geom type="mesh" mesh="mesh_ll_dg_2_4" contype="1" conaffinity="1" />
                                      <joint name="lj_dg_2_4" type="hinge" axis="0.0 1.0 0.0" range="-1.5707963267948966 1.5707963267948966" />
                                      <body name="ll_dg_2_tip" pos="0.0 0.0 0.0255">
                                        <inertial pos="0.0038063 5.479e-07 0.007157" mass="0.005" fullinertia="1e-06 1e-06 1e-06 2.1191e-12 1.3375e-08 -3.0731e-11" />
                                        <geom type="mesh" mesh="mesh_ll_dg_2_tip" contype="1" conaffinity="1" />
                                        <site name="left_index_tip_site" pos="0 0 0" size="0.002 0.002 0.002" group="2"/>
                                      </body>
                                    </body>
                                  </body>
                                </body>
                              </body>
                              <body name="ll_dg_3_1" pos="-0.0071 -0.0025 0.0701">
                                <inertial pos="0.0012558 -0.00017703 0.023374" mass="0.045" fullinertia="6.233e-06 9.3331e-06 6.7817e-06 1.1315e-07 -1.1589e-06 3.5383e-08" />
                                <geom type="mesh" mesh="mesh_ll_dg_3_1" contype="1" conaffinity="1" />
                                <joint name="lj_dg_3_1" type="hinge" axis="1.0 0.0 0.0" range="-0.6108652381980153 0.6108652381980153" />
                                <body name="ll_dg_3_2" pos="0.01765 0.0 0.0265">
                                  <inertial pos="-4.7446e-06 2.3008e-05 0.023958" mass="0.045" fullinertia="6.4181e-06 5.9794e-06 2.458e-06 1.3678e-09 -2.3552e-09 3.6014e-07" />
                                  <geom type="mesh" mesh="mesh_ll_dg_3_2" contype="1" conaffinity="1" />
                                  <joint name="lj_dg_3_2" type="hinge" axis="0.0 1.0 0.0" range="0.0 1.9547687622336491" />
                                  <body name="ll_dg_3_3" pos="0.0 0.0 0.0388">
                                    <inertial pos="-4.7446e-06 2.3008e-05 0.023958" mass="0.045" fullinertia="6.4181e-06 5.9794e-06 2.458e-06 1.3678e-09 -2.3552e-09 3.6014e-07" />
                                    <geom type="mesh" mesh="mesh_ll_dg_3_3" contype="1" conaffinity="1" />
                                    <joint name="lj_dg_3_3" type="hinge" axis="0.0 1.0 0.0" range="-1.5707963267948966 1.5707963267948966" />
                                    <body name="ll_dg_3_4" pos="0.0 0.0 0.0388">
                                      <inertial pos="-0.00070816 0.00043036 0.017842" mass="0.025" fullinertia="2.8592e-06 2.3907e-06 1.6592e-06 -5.9306e-09 2.1028e-07 1.8286e-07" />
                                      <geom type="mesh" mesh="mesh_ll_dg_3_4" contype="1" conaffinity="1" />
                                      <joint name="lj_dg_3_4" type="hinge" axis="0.0 1.0 0.0" range="-1.5707963267948966 1.5707963267948966" />
                                      <body name="ll_dg_3_tip" pos="0.0 0.0 0.0255">
                                        <inertial pos="0.0038063 5.479e-07 0.007157" mass="0.005" fullinertia="1e-06 1e-06 1e-06 2.1191e-12 1.3375e-08 -3.0731e-11" />
                                        <geom type="mesh" mesh="mesh_ll_dg_3_tip" contype="1" conaffinity="1" />
                                        <site name="left_middle_tip_site" pos="0 0 0" size="0.002 0.002 0.002" group="2"/>
                                      </body>
                                    </body>
                                  </body>
                                </body>
                              </body>
                              <body name="ll_dg_4_1" pos="-0.0071 0.022 0.0621">
                                <inertial pos="0.001061 0.00024417 0.023499" mass="0.045" fullinertia="6.5538e-06 9.5305e-06 7.0877e-06 3.9294e-08 -1.1507e-06 7.6072e-08" />
                                <geom type="mesh" mesh="mesh_ll_dg_4_1" contype="1" conaffinity="1" />
                                <joint name="lj_dg_4_1" type="hinge" axis="1.0 0.0 0.0" range="-0.4188790204786391 0.6108652381980153" />
                                <body name="ll_dg_4_2" pos="0.01765 0.0 0.0265">
                                  <inertial pos="-4.7446e-06 2.3008e-05 0.023958" mass="0.045" fullinertia="6.4181e-06 5.9794e-06 2.458e-06 1.3678e-09 -2.3552e-09 3.6014e-07" />
                                  <geom type="mesh" mesh="mesh_ll_dg_4_2" contype="1" conaffinity="1" />
                                  <joint name="lj_dg_4_2" type="hinge" axis="0.0 1.0 0.0" range="0.0 1.9024088846738192" />
                                  <body name="ll_dg_4_3" pos="0.0 0.0 0.0388">
                                    <inertial pos="-4.7446e-06 2.3008e-05 0.023958" mass="0.045" fullinertia="6.4181e-06 5.9794e-06 2.458e-06 1.3678e-09 -2.3552e-09 3.6014e-07" />
                                    <geom type="mesh" mesh="mesh_ll_dg_4_3" contype="1" conaffinity="1" />
                                    <joint name="lj_dg_4_3" type="hinge" axis="0.0 1.0 0.0" range="-1.5707963267948966 1.5707963267948966" />
                                    <body name="ll_dg_4_4" pos="0.0 0.0 0.0388">
                                      <inertial pos="-0.00070816 0.00043036 0.017842" mass="0.025" fullinertia="2.8592e-06 2.3907e-06 1.6592e-06 -5.9306e-09 2.1028e-07 1.8286e-07" />
                                      <geom type="mesh" mesh="mesh_ll_dg_4_4" contype="1" conaffinity="1" />
                                      <joint name="lj_dg_4_4" type="hinge" axis="0.0 1.0 0.0" range="-1.5707963267948966 1.5707963267948966" />
                                      <body name="ll_dg_4_tip" pos="0.0 0.0 0.0255">
                                        <inertial pos="0.0038063 5.479e-07 0.007157" mass="0.005" fullinertia="1e-06 1e-06 1e-06 2.1191e-12 1.3375e-08 -3.0731e-11" />
                                        <geom type="mesh" mesh="mesh_ll_dg_4_tip" contype="1" conaffinity="1" />
                                        <site name="left_ring_tip_site" pos="0 0 0" size="0.002 0.002 0.002" group="2"/>
                                      </body>
                                    </body>
                                  </body>
                                </body>
                              </body>
                              <body name="ll_dg_5_1" pos="0.0103 0.0195 0.0182">
                                <inertial pos="-0.0045287 0.025016 0.014025" mass="0.055" fullinertia="2.3621e-05 2.3655e-05 1.1298e-05 -2.0571e-07 2.5894e-06 -4.4786e-06" />
                                <geom type="mesh" mesh="mesh_ll_dg_5_1" contype="1" conaffinity="1" />
                                <joint name="lj_dg_5_1" type="hinge" axis="0.0 0.0 1.0" range="-1.0471975511965976 0.017453292519943295" />
                                <body name="ll_dg_5_2" pos="0.0 0.028 0.0381">
                                  <inertial pos="0.00055633 0.00055633 0.0155" mass="0.025" fullinertia="1.9935e-06 1.9935e-06 1.459e-06 3.114e-09 1.5774e-07 -1.5774e-07" />
                                  <geom type="mesh" mesh="mesh_ll_dg_5_2" contype="1" conaffinity="1" />
                                  <joint name="lj_dg_5_2" type="hinge" axis="1.0 0.0 0.0" range="-0.6108652381980153 0.4188790204786391" />
                                  <body name="ll_dg_5_3" pos="0.0 0.0 0.031">
                                    <inertial pos="4.7446e-06 2.3008e-05 0.014842" mass="0.045" fullinertia="6.4181e-06 5.9794e-06 2.458e-06 -1.3678e-09 -2.3552e-09 -3.6014e-07" />
                                    <geom type="mesh" mesh="mesh_ll_dg_5_3" contype="1" conaffinity="1" />
                                    <joint name="lj_dg_5_3" type="hinge" axis="0.0 1.0 0.0" range="-1.5707963267948966 1.5707963267948966" />
                                    <body name="ll_dg_5_4" pos="0.0 0.0 0.0388">
                                      <inertial pos="-0.00036539 -0.00020482 0.018795" mass="0.045" fullinertia="9.8194e-06 9.4915e-06 2.9391e-06 3.4626e-09 3.7813e-07 -1.5157e-07" />
                                      <geom type="mesh" mesh="mesh_ll_dg_5_4" contype="1" conaffinity="1" />
                                      <joint name="lj_dg_5_4" type="hinge" axis="0.0 1.0 0.0" range="-1.5707963267948966 1.5707963267948966" />
                                      <body name="ll_dg_5_tip" pos="0.0 0.0 0.0363">
                                        <inertial pos="0.0038063 5.479e-07 0.007157" mass="0.005" fullinertia="1e-06 1e-06 1e-06 2.1191e-12 1.3375e-08 -3.0731e-11" />
                                        <geom type="mesh" mesh="mesh_ll_dg_5_tip" contype="1" conaffinity="1" />
                                        <site name="left_pinky_tip_site" pos="0 0 0" size="0.002 0.002 0.002" group="2"/>
                                      </body>
                                    </body>
                                  </body>
                                </body>
                              </body>
                            </body>
                          </body>
                        </body>
                      </body>
                    </body>
                  </body>
                </body>
              </body>
            </body>
          </body>
        </body>
      </body>
    </body>
    <body name="right_robot_base" pos="-0.45 0.4 0.945" quat="0.988 0 0 -0.154">
      <body name="panda_link0">
        <inertial pos="-0.041018 -0.00014 0.049974" mass="0.629769" fullinertia="0.00315 0.00388 0.004285 8.2904e-07 0.00015 8.2299e-06" />
        <geom type="mesh" mesh="mesh_panda_link0" contype="1" conaffinity="1" />
        <body name="panda_link1" pos="0.0 0.0 0.333">
          <inertial pos="0.003875 0.002081 -0.04762" mass="4.970684" fullinertia="0.70337 0.70661 0.009117 -0.000139 0.006772 0.019169" />
          <geom type="mesh" mesh="mesh_panda_link1" contype="1" conaffinity="1" />
          <joint name="panda_right_joint1" type="hinge" axis="0.0 0.0 1.0" range="-2.8973 2.8973" />
          <body name="panda_link2" euler="-1.5707963267948966 0.0 0.0">
            <inertial pos="-0.003141 -0.02872 0.003495" mass="0.646926" fullinertia="0.007962 0.02811 0.025995 -0.003925 0.010254 0.000704" />
            <geom type="mesh" mesh="mesh_panda_link2" contype="1" conaffinity="1" />
            <joint name="panda_right_joint2" type="hinge" axis="0.0 0.0 1.0" range="-1.7628 1.7628" />
            <body name="panda_link3" pos="0.0 -0.316 0.0" euler="1.5707963267948966 0.0 0.0">
              <inertial pos="0.027518 0.039252 -0.066502" mass="3.228604" fullinertia="0.037242 0.036155 0.01083 -0.004761 -0.011396 -0.012805" />
              <geom type="mesh" mesh="mesh_panda_link3" contype="1" conaffinity="1" />
              <joint name="panda_right_joint3" type="hinge" axis="0.0 0.0 1.0" range="-2.8973 2.8973" />
              <body name="panda_link4" pos="0.0825 0.0 0.0" euler="1.5707963267948966 0.0 0.0">
                <inertial pos="-0.05317 0.104419 0.027454" mass="3.587895" fullinertia="0.025853 0.019552 0.028323 0.007796 -0.001332 0.008641" />
                <geom type="mesh" mesh="mesh_panda_link4" contype="1" conaffinity="1" />
                <joint name="panda_right_joint4" type="hinge" axis="0.0 0.0 1.0" range="-3.0718 -0.0698" />
                <body name="panda_link5" pos="-0.0825 0.384 0.0" euler="-1.5707963267948966 0.0 0.0">
                  <inertial pos="-0.011953 0.041065 -0.038437" mass="1.225946" fullinertia="0.035549 0.029474 0.008627 -0.002117 -0.004037 0.000229" />
                  <geom type="mesh" mesh="mesh_panda_link5" contype="1" conaffinity="1" />
                  <joint name="panda_right_joint5" type="hinge" axis="0.0 0.0 1.0" range="-2.8973 2.8973" />
                  <body name="panda_link6" euler="1.5707963267948966 0.0 0.0">
                    <inertial pos="0.060149 -0.014117 -0.010517" mass="1.666555" fullinertia="0.001964 0.004354 0.005433 0.000109 -0.001158 0.000341" />
                    <geom type="mesh" mesh="mesh_panda_link6" contype="1" conaffinity="1" />
                    <joint name="panda_right_joint6" type="hinge" axis="0.0 0.0 1.0" range="-0.0175 3.7525" />
                    <body name="panda_link7" pos="0.088 0.0 0.0" euler="1.5707963267948966 0.0 0.0">
                      <inertial pos="0.010517 -0.004252 0.061597" mass="0.735522" fullinertia="0.012516 0.010027 0.004815 -0.000428 -0.001196 -0.000741" />
                      <geom type="mesh" mesh="mesh_panda_link7" contype="1" conaffinity="1" />
                      <joint name="panda_right_joint7" type="hinge" axis="0.0 0.0 1.0" range="-2.8973 2.8973" />
                      <body name="panda_link8">
                        <inertial pos="0 0 0" mass="0.001" diaginertia="1e-06 1e-06 1e-06" />
                        <body name="rl_dg_mount" pos="0.0 0.0 0.1034" euler="0.0 0.0 -0.5">
                          <inertial pos="-6.4721e-09 -2.1674e-05 0.0049997" mass="0.05" fullinertia="1.0999e-05 1.1018e-05 2.0531e-05 -2.1734e-12 1.2441e-12 4.0435e-09" />
                          <geom type="mesh" mesh="mesh_rl_dg_mount" contype="1" conaffinity="1" />
                          <body name="rl_dg_base" pos="0.0 0.0 0.004">
                            <inertial pos="-0.00058969 0.0005138 0.037363" mass="0.45" fullinertia="0.00048608 0.00049085 0.00043369 1.041e-05 1.7229e-05 -5.1908e-06" />
                            <geom type="mesh" mesh="mesh_rl_dg_base" contype="1" conaffinity="1" />
                            <body name="rl_dg_palm" pos="0.0 0.0 0.0698">
                              <inertial pos="-0.0089577 0.00095577 0.041325" mass="0.35" fullinertia="0.00052656 0.00041654 0.00045783 2.513e-06 -2.2304e-05 -4.8956e-05" />
                              <geom type="mesh" mesh="mesh_rl_dg_palm" contype="1" conaffinity="1" />
                              <site name="right_palm_site" pos="0 0 0.02" size="0.002 0.002 0.002" group="2"/>
                              <body name="rl_dg_1_1" pos="-0.0162 0.019 0.0128">
                                <inertial pos="0.021473 3.1163e-06 0.0028146" mass="0.045" fullinertia="4.2707e-06 1.3718e-05 1.2161e-05 2.4123e-09 2.9055e-06 -1.3824e-09" />
                                <geom type="mesh" mesh="mesh_rl_dg_1_1" contype="1" conaffinity="1" />
                                <joint name="rj_dg_1_1" type="hinge" axis="1.0 0.0 0.0" range="-0.3839724354387525 0.8901179185171081" />
                                <body name="rl_dg_1_2" pos="0.04195 0.0 0.0">
                                  <inertial pos="0.00055633 0.0155 0.00055633" mass="0.025" fullinertia="1.9935e-06 1.459e-06 1.9935e-06 -1.5774e-07 3.114e-09 1.5774e-07" />
                                  <geom type="mesh" mesh="mesh_rl_dg_1_2" contype="1" conaffinity="1" />
                                  <joint name="rj_dg_1_2" type="hinge" axis="0.0 0.0 1.0" range="-3.141592653589793 0.0" />
                                  <body name="rl_dg_1_3" pos="0.0 0.031 0.0">
                                    <inertial pos="2.3008e-05 0.014842 4.7446e-06" mass="0.045" fullinertia="5.9794e-06 2.458e-06 6.4181e-06 -3.6014e-07 -1.3678e-09 -2.3552e-09" />
                                    <geom type="mesh" mesh="mesh_rl_dg_1_3" contype="1" conaffinity="1" />
                                    <joint name="rj_dg_1_3" type="hinge" axis="1.0 0.0 0.0" range="-1.5707963267948966 1.5707963267948966" />
                                    <body name="rl_dg_1_4" pos="0.0 0.0388 0.0">
                                      <inertial pos="-0.00020482 0.018795 -0.00036539" mass="0.045" fullinertia="9.4915e-06 2.9391e-06 9.8194e-06 -1.5157e-07 3.4626e-09 3.7813e-07" />
                                      <geom type="mesh" mesh="mesh_rl_dg_1_4" contype="1" conaffinity="1" />
                                      <joint name="rj_dg_1_4" type="hinge" axis="1.0 0.0 0.0" range="-1.5707963267948966 1.5707963267948966" />
                                      <body name="rl_dg_1_tip" pos="0.0 0.0363 0.0">
                                        <inertial pos="5.479e-07 0.007157 0.0038063" mass="0.005" fullinertia="1e-06 1e-06 1e-06 -3.0731e-11 2.1191e-12 1.3375e-08" />
                                        <geom type="mesh" mesh="mesh_rl_dg_1_tip" contype="1" conaffinity="1" />
                                        <site name="right_thumb_tip_site" pos="0 0 0" size="0.002 0.002 0.002" group="2"/>
                                      </body>
                                    </body>
                                  </body>
                                </body>
                              </body>
                              <body name="rl_dg_2_1" pos="-0.0071 0.027 0.0661">
                                <inertial pos="0.001061 0.00024417 0.023499" mass="0.045" fullinertia="6.5538e-06 9.5305e-06 7.0877e-06 3.9294e-08 -1.1507e-06 7.6072e-08" />
                                <geom type="mesh" mesh="mesh_rl_dg_2_1" contype="1" conaffinity="1" />
                                <joint name="rj_dg_2_1" type="hinge" axis="1.0 0.0 0.0" range="-0.4188790204786391 0.6108652381980153" />
                                <body name="rl_dg_2_2" pos="0.01765 0.0 0.0265">
                                  <inertial pos="-4.7446e-06 2.3008e-05 0.023958" mass="0.045" fullinertia="6.4181e-06 5.9794e-06 2.458e-06 1.3678e-09 -2.3552e-09 3.6014e-07" />
                                  <geom type="mesh" mesh="mesh_rl_dg_2_2" contype="1" conaffinity="1" />
                                  <joint name="rj_dg_2_2" type="hinge" axis="0.0 1.0 0.0" range="-0.0 2.007128639793479" />
                                  <body name="rl_dg_2_3" pos="0.0 0.0 0.0388">
                                    <inertial pos="-4.7446e-06 2.3008e-05 0.023958" mass="0.045" fullinertia="6.4181e-06 5.9794e-06 2.458e-06 1.3678e-09 -2.3552e-09 3.6014e-07" />
                                    <geom type="mesh" mesh="mesh_rl_dg_2_3" contype="1" conaffinity="1" />
                                    <joint name="rj_dg_2_3" type="hinge" axis="0.0 1.0 0.0" range="-1.5707963267948966 1.5707963267948966" />
                                    <body name="rl_dg_2_4" pos="0.0 0.0 0.0388">
                                      <inertial pos="-0.00070816 0.00043036 0.017842" mass="0.025" fullinertia="2.8592e-06 2.3907e-06 1.6592e-06 -5.9306e-09 2.1028e-07 1.8286e-07" />
                                      <geom type="mesh" mesh="mesh_rl_dg_2_4" contype="1" conaffinity="1" />
                                      <joint name="rj_dg_2_4" type="hinge" axis="0.0 1.0 0.0" range="-1.5707963267948966 1.5707963267948966" />
                                      <body name="rl_dg_2_tip" pos="0.0 0.0 0.0255">
                                        <inertial pos="0.0038062910498208 5.47903831610297e-07 0.00715699051285251" mass="0.005" fullinertia="1e-06 1e-06 1e-06 2.11907398040965e-12 1.337493321886e-08 -3.07311776926212e-11" />
                                        <geom type="mesh" mesh="mesh_rl_dg_2_tip" contype="1" conaffinity="1" />
                                        <site name="right_index_tip_site" pos="0 0 0" size="0.002 0.002 0.002" group="2"/>
                                      </body>
                                    </body>
                                  </body>
                                </body>
                              </body>
                              <body name="rl_dg_3_1" pos="-0.0071 0.0025 0.0701">
                                <inertial pos="0.0012558 -0.00017703 0.023374" mass="0.045" fullinertia="6.233e-06 9.3331e-06 6.7817e-06 1.1315e-07 -1.1589e-06 3.5383e-08" />
                                <geom type="mesh" mesh="mesh_rl_dg_3_1" contype="1" conaffinity="1" />
                                <joint name="rj_dg_3_1" type="hinge" axis="1.0 0.0 0.0" range="-0.6108652381980153 0.6108652381980153" />
                                <body name="rl_dg_3_2" pos="0.01765 0.0 0.0265">
                                  <inertial pos="-4.7446e-06 2.3008e-05 0.023958" mass="0.045" fullinertia="6.4181e-06 5.9794e-06 2.458e-06 1.3678e-09 -2.3552e-09 3.6014e-07" />
                                  <geom type="mesh" mesh="mesh_rl_dg_3_2" contype="1" conaffinity="1" />
                                  <joint name="rj_dg_3_2" type="hinge" axis="0.0 1.0 0.0" range="0.0 1.9547687622336491" />
                                  <body name="rl_dg_3_3" pos="0.0 0.0 0.0388">
                                    <inertial pos="-4.7446e-06 2.3008e-05 0.023958" mass="0.045" fullinertia="6.4181e-06 5.9794e-06 2.458e-06 1.3678e-09 -2.3552e-09 3.6014e-07" />
                                    <geom type="mesh" mesh="mesh_rl_dg_3_3" contype="1" conaffinity="1" />
                                    <joint name="rj_dg_3_3" type="hinge" axis="0.0 1.0 0.0" range="-1.5707963267948966 1.5707963267948966" />
                                    <body name="rl_dg_3_4" pos="0.0 0.0 0.0388">
                                      <inertial pos="-0.00070816 0.00043036 0.017842" mass="0.025" fullinertia="2.8592e-06 2.3907e-06 1.6592e-06 -5.9306e-09 2.1028e-07 1.8286e-07" />
                                      <geom type="mesh" mesh="mesh_rl_dg_3_4" contype="1" conaffinity="1" />
                                      <joint name="rj_dg_3_4" type="hinge" axis="0.0 1.0 0.0" range="-1.5707963267948966 1.5707963267948966" />
                                      <body name="rl_dg_3_tip" pos="0.0 0.0 0.0255">
                                        <inertial pos="0.0038062910498208 5.47903831610297e-07 0.00715699051285251" mass="0.005" fullinertia="1e-06 1e-06 1e-06 2.11907398040965e-12 1.337493321886e-08 -3.07311776926212e-11" />
                                        <geom type="mesh" mesh="mesh_rl_dg_3_tip" contype="1" conaffinity="1" />
                                        <site name="right_middle_tip_site" pos="0 0 0" size="0.002 0.002 0.002" group="2"/>
                                      </body>
                                    </body>
                                  </body>
                                </body>
                              </body>
                              <body name="rl_dg_4_1" pos="-0.0071 -0.022 0.0621">
                                <inertial pos="6.0566e-05 -0.00058566 0.023499" mass="0.045" fullinertia="6.5541e-06 9.5306e-06 7.0879e-06 1.8684e-07 -1.1508e-06 -5.3298e-09" />
                                <geom type="mesh" mesh="mesh_rl_dg_4_1" contype="1" conaffinity="1" />
                                <joint name="rj_dg_4_1" type="hinge" axis="1.0 0.0 0.0" range="-0.6108652381980153 0.4188790204786391" />
                                <body name="rl_dg_4_2" pos="0.01765 0.0 0.0265">
                                  <inertial pos="-4.7446e-06 2.3008e-05 0.023958" mass="0.045" fullinertia="6.4181e-06 5.9794e-06 2.458e-06 1.3678e-09 -2.3552e-09 3.6014e-07" />
                                  <geom type="mesh" mesh="mesh_rl_dg_4_2" contype="1" conaffinity="1" />
                                  <joint name="rj_dg_4_2" type="hinge" axis="0.0 1.0 0.0" range="0.0 1.9024088846738192" />
                                  <body name="rl_dg_4_3" pos="0.0 0.0 0.0388">
                                    <inertial pos="-4.7446e-06 2.3008e-05 0.023958" mass="0.045" fullinertia="6.4181e-06 5.9794e-06 2.458e-06 1.3678e-09 -2.3552e-09 3.6014e-07" />
                                    <geom type="mesh" mesh="mesh_rl_dg_4_3" contype="1" conaffinity="1" />
                                    <joint name="rj_dg_4_3" type="hinge" axis="0.0 1.0 0.0" range="-1.5707963267948966 1.5707963267948966" />
                                    <body name="rl_dg_4_4" pos="0.0 0.0 0.0388">
                                      <inertial pos="-0.00070816 0.00043036 0.017842" mass="0.025" fullinertia="2.8592e-06 2.3907e-06 1.6592e-06 -5.9306e-09 2.1028e-07 1.8286e-07" />
                                      <geom type="mesh" mesh="mesh_rl_dg_4_4" contype="1" conaffinity="1" />
                                      <joint name="rj_dg_4_4" type="hinge" axis="0.0 1.0 0.0" range="-1.5707963267948966 1.5707963267948966" />
                                      <body name="rl_dg_4_tip" pos="0.0 0.0 0.0255">
                                        <inertial pos="0.0038062910498208 5.47903831610297e-07 0.00715699051285251" mass="0.005" fullinertia="1e-06 1e-06 1e-06 2.11907398040965e-12 1.337493321886e-08 -3.07311776926212e-11" />
                                        <geom type="mesh" mesh="mesh_rl_dg_4_tip" contype="1" conaffinity="1" />
                                        <site name="right_ring_tip_site" pos="0 0 0" size="0.002 0.002 0.002" group="2"/>
                                      </body>
                                    </body>
                                  </body>
                                </body>
                              </body>
                              <body name="rl_dg_5_1" pos="0.0103 -0.0195 0.0182">
                                <inertial pos="-0.00433013582483537 -0.0250157327042134 0.0140244480786593" mass="0.055" fullinertia="2.36207639664085e-05 2.36540063110524e-05 1.12977296557035e-05 2.93907895931127e-07 2.26324366936635e-06 4.47865100758349e-06" />
                                <geom type="mesh" mesh="mesh_rl_dg_5_1" contype="1" conaffinity="1" />
                                <joint name="rj_dg_5_1" type="hinge" axis="0.0 0.0 1.0" range="-0.017453292519943295 1.0471975511965976" />
                                <body name="rl_dg_5_2" pos="0.0 -0.028 0.0381">
                                  <inertial pos="-0.000537630631570108 0.000537630708726741 0.0155000698139622" mass="0.025" fullinertia="1.99384439440442e-06 1.99384475671682e-06 1.4598228332417e-06 -8.19844977566199e-09 -1.59465145750793e-07 -1.59463723420756e-07" />
                                  <geom type="mesh" mesh="mesh_rl_dg_5_2" contype="1" conaffinity="1" />
                                  <joint name="rj_dg_5_2" type="hinge" axis="1.0 0.0 0.0" range="-0.4188790204786391 0.6108652381980153" />
                                  <body name="rl_dg_5_3" pos="0.0 0.0 0.031">
                                    <inertial pos="4.7446492172469e-06 2.30083649378834e-05 0.0148418615456518" mass="0.045" fullinertia="6.41805423935041e-06 5.97938336588576e-06 2.4580051713906e-06 -1.36778125377832e-09 -2.35515982623531e-09 -3.60143752502035e-07" />
                                    <geom type="mesh" mesh="mesh_rl_dg_5_3" contype="1" conaffinity="1" />
                                    <joint name="rj_dg_5_3" type="hinge" axis="0.0 1.0 0.0" range="-1.5707963267948966 1.5707963267948966" />
                                    <body name="rl_dg_5_4" pos="0.0 0.0 0.0388">
                                      <inertial pos="-0.000365388872256418 -0.000204821110631699 0.0187946706549663" mass="0.045" fullinertia="9.81936385229629e-06 9.49149264777591e-06 2.93905089746507e-06 3.46258177073373e-09 3.7813020115566e-07 -1.51572680457615e-07" />
                                      <geom type="mesh" mesh="mesh_rl_dg_5_4" contype="1" conaffinity="1" />
                                      <joint name="rj_dg_5_4" type="hinge" axis="0.0 1.0 0.0" range="-1.5707963267948966 1.5707963267948966" />
                                      <body name="rl_dg_5_tip" pos="0.0 0.0 0.0363">
                                        <inertial pos="0.0038062910498208 5.47903831610297e-07 0.00715699051285251" mass="0.005" fullinertia="1e-06 1e-06 1e-06 2.11907398040965e-12 1.337493321886e-08 -3.07311776926212e-11" />
                                        <geom type="mesh" mesh="mesh_rl_dg_5_tip" contype="1" conaffinity="1" />
                                        <site name="right_pinky_tip_site" pos="0 0 0" size="0.002 0.002 0.002" group="2"/>
                                      </body>
                                    </body>
                                  </body>
                                </body>
                              </body>
                            </body>
                          </body>
                        </body>
                      </body>
                    </body>
                  </body>
                </body>
              </body>
            </body>
          </body>
        </body>
      </body>
    </body>
    <body mocap="true" name="right-wrist" pos="0.47 -0.3 0.9" quat="0 0.7071 0.7071 0">
      <site pos="0 0 0" name="right-wrist-site-mocap" rgba="1 0 0 1" size="0.005 0.005 0.005" group="2"/>
    </body>
    <body mocap="true" name="right-thumb-tip" pos="0.56 -0.43 0.917" quat="0.2706 0.6533 0.2706 -0.6533">
      <site pos="0 0 0" name="right-thumb-tip-site-mocap" rgba="1 0 0 1" size="0.005 0.005 0.005" group="2"/>
    </body>
    <body mocap="true" name="right-index-finger-tip" pos="0.65 -0.33 0.9" quat="0 0.7071 0.7071 0">
      <site pos="0 0 0" name="right-index-finger-tip-site-mocap" rgba="1 0 0 1" size="0.005 0.005 0.005" group="2"/>
    </body>
    <body mocap="true" name="right-middle-finger-tip" pos="0.655 -0.31 0.9" quat="0 0.7071 0.7071 0">
      <site pos="0 0 0" name="right-middle-finger-tip-site-mocap" rgba="1 0 0 1" size="0.005 0.005 0.005" group="2"/>
    </body>
    <body mocap="true" name="right-ring-finger-tip" pos="0.649 -0.29 0.9" quat="0 0.7071 0.7071 0">
      <site pos="0 0 0" name="right-ring-finger-tip-site-mocap" rgba="1 0 0 1" size="0.005 0.005 0.005" group="2"/>
    </body>
    <body mocap="true" name="right-pinky-finger-tip" pos="0.643 -0.27 0.9" quat="0 0.7071 0.7071 0">
      <site pos="0 0 0" name="right-pinky-finger-tip-site-mocap" rgba="1 0 0 1" size="0.005 0.005 0.005" group="2"/>
    </body>
    <body mocap="true" name="left-wrist" pos="-0.33 -0.3 0.9" quat="0 0.7071 0.7071 0">
      <site pos="0 0 0" name="left-wrist-site-mocap" rgba="1 0 0 1" size="0.005 0.005 0.005" group="2"/>
    </body>
    <body mocap="true" name="left-thumb-tip" pos="-0.24 -0.17 0.917" quat="0.6533 -0.2706 -0.6533 -0.2706">
      <site pos="0 0 0" name="left-thumb-tip-site-mocap" rgba="1 0 0 1" size="0.005 0.005 0.005" group="2"/>
    </body>
    <body mocap="true" name="left-index-finger-tip" pos="-0.15 -0.27 0.9" quat="0 0.7071 0.7071 0">
      <site pos="0 0 0" name="left-index-finger-tip-site-mocap" rgba="1 0 0 1" size="0.005 0.005 0.005" group="2"/>
    </body>
    <body mocap="true" name="left-middle-finger-tip" pos="-0.145 -0.29 0.9" quat="0 0.7071 0.7071 0">
      <site pos="0 0 0" name="left-middle-finger-tip-site-mocap" rgba="1 0 0 1" size="0.005 0.005 0.005" group="2"/>
    </body>
    <body mocap="true" name="left-ring-finger-tip" pos="-0.151 -0.31 0.9" quat="0 0.7071 0.7071 0">
      <site pos="0 0 0" name="left-ring-finger-tip-site-mocap" rgba="1 0 0 1" size="0.005 0.005 0.005" group="2"/>
    </body>
    <body mocap="true" name="left-pinky-finger-tip" pos="-0.157 -0.33 0.9" quat="0 0.7071 0.7071 0">
      <site pos="0 0 0" name="left-pinky-finger-tip-site-mocap" rgba="1 0 0 1" size="0.005 0.005 0.005" group="2"/>
    </body>
  </worldbody>
  <equality>
    <weld site1="right-wrist-site-mocap" site2="right_palm_site"/>
    <weld site1="right-thumb-tip-site-mocap" site2="right_thumb_tip_site"/>
    <weld site1="right-index-finger-tip-site-mocap" site2="right_index_tip_site"/>
    <weld site1="right-middle-finger-tip-site-mocap" site2="right_middle_tip_site"/>
    <weld site1="right-ring-finger-tip-site-mocap" site2="right_ring_tip_site"/>
    <weld site1="right-pinky-finger-tip-site-mocap" site2="right_pinky_tip_site"/>
    <weld site1="left-wrist-site-mocap" site2="left_palm_site"/>
    <weld site1="left-thumb-tip-site-mocap" site2="left_thumb_tip_site"/>
    <weld site1="left-index-finger-tip-site-mocap" site2="left_index_tip_site"/>
    <weld site1="left-middle-finger-tip-site-mocap" site2="left_middle_tip_site"/>
    <weld site1="left-ring-finger-tip-site-mocap" site2="left_ring_tip_site"/>
    <weld site1="left-pinky-finger-tip-site-mocap" site2="left_pinky_tip_site"/>
  </equality>
  <!-- Initial pose: qpos order = box(7) then left_arm(7) left_hand(20) right_arm(7) right_hand(20). Edit values 8-61 to change robot pose. -->
  <keyframe>
    <key name="home" qpos="-0.02 -0.1876 1.1835 0 0 1 0  0.12851247 -0.74926734 0.01523919 -2.5314567 1.3384545 1.8232623 0.72626555 -0.4 0.07 -0.81 0.23 0.14 0.44 0.31 -0.29 0.08 0.52 0.51 -1.03 0.1 0.77 -0.33 -0.56 -0.43 0.03 -0.12 1.21 -0.30540678 -0.79184073 0.06812683 -2.5840569 -1.3527942 2.0385659 0.62929636 0.3 -0.04 0.6 -0.02 -0.08 0.23 0.25 -0.22 -0.07 0.08 0.69 -0.82 -0.04 0.28 -0.02 -0.17 0. 0. 0.71 -1.33" />
  </keyframe>
</mujoco>